Workbook
Name RateYears: tblRates[year_of_income]

Sheet Start Here
A1: Division 7A loan review: s 109N terms and s 109E minimum yearly repayment
A3: 1. On Register, paste one amalgamated loan per row over the example rows, using the same columns as the CSV the command line tool reads. Booleans are true, false or unknown; a blank is unknown. Rates are fractions (8.77 per cent is 0.0877). Years are written 2026-27.
A4: 2. On Summary, choose the year of income to review. The s 109N gate reads each loan's benchmark from the year the loan was made; the repayment uses the chosen year's rate.
A5: 3. Read the calculated columns on Register: each s 109N(1) limb, the gate verdict, the s 109E(6) repayment, the shortfall and the experimental exposure. REFUSED and UNKNOWN are answers, never a number; the reason column says why.
A6: 4. Review Checks: BLOCKED means the register cannot be read (a bad year label, a value that is not true, false or unknown, text where a number belongs, a formula pasted into an input, or no reviewed rate for the year). REVIEW means a loan is not on s 109N terms, a repayment is short, a row is undecided, or a repayment figure is refused (read the reason; refusal alone is not a breach). PASS means nothing exposed, nothing undecided.
A7: 5. A rising benchmark rate raises the minimum yearly repayment on existing complying loans, not just on new ones: s 109E(6) uses the current year's rate.
A8: 6. Experimental review aid. Not a Division 7A determination. The shortfall is not the dividend (s 109Y, s 109Q and s 109RB are not modelled) and s 109R is not applied.
A10: Overall status
A11: ='Review Checks'!B10 -> REVIEW
A13: div7a-loan-review workbook, engine 0.3.1. Macro-free. Not advice; see DISCLAIMER.md in the repository.

Sheet Register
A1: loan_id | B1: borrower_reference | C1: year_loan_made | D1: written_agreement | E1: terms_in_place_before_lodgment_day | F1: maximum_term_years | G1: secured_by_registered_mortgage_over_real_property | H1: security_coverage_at_first_made | I1: interest_rate_for_years_after_year_loan_made | J1: amalgamated_loan_unpaid_at_end_of_previous_year | K1: remaining_term_years | L1: payments_applied_during_the_year | M1: out_of_scope_reason | N1: year_of_income_being_tested | O1: Status | P1: Floor_year | Q1: Floor_rate | R1: Limb_a_written | S1: Limb_lodgment | T1: Limb_b_rate | U1: Limb_secured | V1: Allowed_term_raw | W1: Limb_c_term | X1: Gate_verdict | Y1: Max_term_allowed | Z1: Term_used | AA1: MYR_raw | AB1: MYR_verdict | AC1: MYR_reason | AD1: MYR_required | AE1: Shortfall | AF1: Exposure | AG1: Undecided | AH1: Guard | AI1: Input_problem | AJ1: Sample_row | AK1: Year_made_text | AL1: Year_tested_text
A2: L-101 | B2: SYN-SHAREHOLDER-A | C2: 2023-24 | D2: true | E2: true | F2: 7 | G2: false | H2: unknown | I2: 0.0827 | J2: 120000 | K2: 3 | L2: 45000 | O2: =IF(TRIM(tblLoans[[#This Row],[out_of_scope_reason]]&"")<>"","SKIPPED",IF(IFERROR(VALUE(LEFT(tblLoans[[#This Row],[Year_made_text]],4))<1998,FALSE),"SKIPPED","REVIEWED")) -> REVIEWED | P2: =IF(OR(LOWER(TRIM(tblLoans[[#This Row],[Year_tested_text]]&""))={"","-","?","n/a","na","unk","unknown"}),tblLoans[[#This Row],[Year_made_text]],tblLoans[[#This Row],[Year_tested_text]]) -> 2023-24 | Q2: =IFERROR(INDEX(tblRates[rate],MATCH(tblLoans[[#This Row],[Floor_year]],tblRates[year_of_income],0)),"") -> 0.0827 | R2: =IF(OR(LOWER(TRIM(tblLoans[[#This Row],[written_agreement]]&""))={"","-","?","n/a","na","unk","unknown"}),"UNKNOWN",IF(OR(LOWER(TRIM(tblLoans[[#This Row],[written_agreement]]&""))={"1","t","true","y","yes"}),"PASS",IF(OR(LOWER(TRIM(tblLoans[[#This Row],[written_agreement]]&""))={"0","f","false","n","no"}),"FAIL","UNKNOWN"))) -> PASS | S2: =IF(OR(LOWER(TRIM(tblLoans[[#This Row],[terms_in_place_before_lodgment_day]]&""))={"","-","?","n/a","na","unk","unknown"}),"UNKNOWN",IF(OR(LOWER(TRIM(tblLoans[[#This Row],[terms_in_place_before_lodgment_day]]&""))={"1","t","true","y","yes"}),"PASS",IF(OR(LOWER(TRIM(tblLoans[[#This Row],[terms_in_place_before_lodgment_day]]&""))={"0","f","false","n","no"}),"FAIL","UNKNOWN"))) -> PASS | T2: =IF(NOT(ISNUMBER(tblLoans[[#This Row],[interest_rate_for_years_after_year_loan_made]])),"UNKNOWN",IF(tblLoans[[#This Row],[Floor_rate]]="","UNKNOWN",IF(tblLoans[[#This Row],[interest_rate_for_years_after_year_loan_made]]>=tblLoans[[#This Row],[Floor_rate]],"PASS","FAIL"))) -> PASS | U2: =IF(OR(LOWER(TRIM(tblLoans[[#This Row],[secured_by_registered_mortgage_over_real_property]]&""))={"","-","?","n/a","na","unk","unknown"}),"UNKNOWN",IF(OR(LOWER(TRIM(tblLoans[[#This Row],[secured_by_registered_mortgage_over_real_property]]&""))={"1","t","true","y","yes"}),"PASS",IF(OR(LOWER(TRIM(tblLoans[[#This Row],[secured_by_registered_mortgage_over_real_property]]&""))={"0","f","false","n","no"}),"FAIL","UNKNOWN"))) -> FAIL | V2: =IF(tblLoans[[#This Row],[Limb_secured]]="FAIL",7,IF(tblLoans[[#This Row],[Limb_secured]]="PASS",IF(ISNUMBER(tblLoans[[#This Row],[security_coverage_at_first_made]]),IF(tblLoans[[#This Row],[security_coverage_at_first_made]]>=1.1,25,7),""),"")) -> 7 | W2: =IF(NOT(ISNUMBER(tblLoans[[#This Row],[maximum_term_years]])),"UNKNOWN",IF(tblLoans[[#This Row],[Allowed_term_raw]]="",IF(tblLoans[[#This Row],[maximum_term_years]]<=7,"PASS","UNKNOWN"),IF(tblLoans[[#This Row],[maximum_term_years]]<=tblLoans[[#This Row],[Allowed_term_raw]],"PASS","FAIL"))) -> PASS | X2: =IF(tblLoans[[#This Row],[Status]]="SKIPPED","",IF(OR(LOWER(TRIM(tblLoans[[#This Row],[Floor_year]]&""))={"","-","?","n/a","na","unk","unknown"}),"UNKNOWN",IF(OR(tblLoans[[#This Row],[Limb_a_written]]="FAIL",tblLoans[[#This Row],[Limb_lodgment]]="FAIL",tblLoans[[#This Row],[Limb_b_rate]]="FAIL",tblLoans[[#This Row],[Limb_c_term]]="FAIL"),"NOT_COMPLYING",IF(OR(tblLoans[[#This Row],[Limb_a_written]]="UNKNOWN",tblLoans[[#This Row],[Limb_lodgment]]="UNKNOWN",tblLoans[[#This Row],[Limb_b_rate]]="UNKNOWN",tblLoans[[#This Row],[Limb_c_term]]="UNKNOWN"),"UNKNOWN","COMPLYING")))) -> COMPLYING | Y2: =IF(OR(tblLoans[[#This Row],[Status]]="SKIPPED",OR(LOWER(TRIM(tblLoans[[#This Row],[Floor_year]]&""))={"","-","?","n/a","na","unk","unknown"})),"",IF(tblLoans[[#This Row],[Allowed_term_raw]]<>"",tblLoans[[#This Row],[Allowed_term_raw]],IF(AND(ISNUMBER(tblLoans[[#This Row],[maximum_term_years]]),tblLoans[[#This Row],[maximum_term_years]]<=7),7,""))) -> 7 | Z2: =IF(tblLoans[[#This Row],[Status]]="SKIPPED","",IF(ISNUMBER(tblLoans[[#This Row],[remaining_term_years]]),ROUNDUP(tblLoans[[#This Row],[remaining_term_years]],0),"")) -> 3 | AA2: =IF(AND(ISNUMBER(tblLoans[[#This Row],[amalgamated_loan_unpaid_at_end_of_previous_year]]),ISNUMBER(Summary!$B$3),Summary!$B$3>0,ISNUMBER(tblLoans[[#This Row],[Term_used]]),tblLoans[[#This Row],[Term_used]]>0),ROUND(tblLoans[[#This Row],[amalgamated_loan_unpaid_at_end_of_previous_year]]*Summary!$B$3/(1-(1/(1+Summary!$B$3))^tblLoans[[#This Row],[Term_used]]),2),"") -> 47212.37 | AB2: =IF(tblLoans[[#This Row],[Status]]="SKIPPED","",IF(OR(tblLoans[[#This Row],[Gate_verdict]]<>"COMPLYING",AND(NOT(OR(LOWER(TRIM(tblLoans[[#This Row],[Year_made_text]]&""))={"","-","?","n/a","na","unk","unknown"})),tblLoans[[#This Row],[Floor_year]]<>tblLoans[[#This Row],[Year_made_text]]),tblLoans[[#This Row],[Year_made_text]]=Summary!$B$2,IFERROR(VALUE(LEFT(tblLoans[[#This Row],[Year_made_text]],4))>Summary!$B$4,FALSE),AND(ISNUMBER(tblLoans[[#This Row],[Term_used]]),tblLoans[[#This Row],[Term_used]]<=0),AND(ISNUMBER(Summary!$B$3),Summary!$B$3<=0)),"REFUSED",IF(OR(OR(LOWER(TRIM(tblLoans[[#This Row],[Year_made_text]]&""))={"","-","?","n/a","na","unk","unknown"}),NOT(ISNUMBER(Summary!$B$3)),NOT(ISNUMBER(tblLoans[[#This Row],[amalgamated_loan_unpaid_at_end_of_previous_year]])),NOT(ISNUMBER(tblLoans[[#This Row],[payments_applied_during_the_year]])),NOT(ISNUMBER(tblLoans[[#This Row],[Term_used]]))),"UNKNOWN",IF(tblLoans[[#This Row],[MYR_raw]]-ROUND(tblLoans[[#This Row],[payments_applied_during_the_year]],2)<=0,"MYR_MET","MYR_SHORT")))) -> MYR_SHORT | AC2: =IF(tblLoans[[#This Row],[MYR_verdict]]="REFUSED",IF(tblLoans[[#This Row],[Gate_verdict]]<>"COMPLYING","s 109N gate is "&tblLoans[[#This Row],[Gate_verdict]]&", so s 109E produces no repayment figure",IF(tblLoans[[#This Row],[Floor_year]]<>tblLoans[[#This Row],[Year_made_text]],"gate benchmark year differs from year_loan_made",IF(tblLoans[[#This Row],[Year_made_text]]=Summary!$B$2,"year of income is the year the loan was made (s 109E(1)(a), s 109P)",IF(IFERROR(VALUE(LEFT(tblLoans[[#This Row],[Year_made_text]],4))>Summary!$B$4,FALSE),"loan made after the year of income",IF(AND(ISNUMBER(tblLoans[[#This Row],[Term_used]]),tblLoans[[#This Row],[Term_used]]<=0),"nil remaining term under s 109E(6)","nil benchmark rate"))))),IF(tblLoans[[#This Row],[MYR_verdict]]="UNKNOWN",IF(OR(LOWER(TRIM(tblLoans[[#This Row],[Year_made_text]]&""))={"","-","?","n/a","na","unk","unknown"}),"year_loan_made not established",IF(NOT(ISNUMBER(Summary!$B$3)),"no reviewed benchmark rate for the year of income",IF(NOT(ISNUMBER(tblLoans[[#This Row],[amalgamated_loan_unpaid_at_end_of_previous_year]])),"unpaid balance at end of previous year not established",IF(NOT(ISNUMBER(tblLoans[[#This Row],[payments_applied_during_the_year]])),"payments applied not established","remaining term not established")))),"")) | AD2: =IF(OR(tblLoans[[#This Row],[MYR_verdict]]="MYR_MET",tblLoans[[#This Row],[MYR_verdict]]="MYR_SHORT"),tblLoans[[#This Row],[MYR_raw]],"") -> 47212.37 | AE2: =IF(OR(tblLoans[[#This Row],[MYR_verdict]]="MYR_MET",tblLoans[[#This Row],[MYR_verdict]]="MYR_SHORT"),MAX(0,ROUND(tblLoans[[#This Row],[MYR_raw]]-ROUND(tblLoans[[#This Row],[payments_applied_during_the_year]],2),2)),"") -> 2212.37 | AF2: =IF(tblLoans[[#This Row],[MYR_verdict]]="MYR_SHORT",tblLoans[[#This Row],[Shortfall]],"") -> 2212.37 | AG2: =IF(AND(tblLoans[[#This Row],[Status]]="REVIEWED",OR(tblLoans[[#This Row],[Gate_verdict]]="UNKNOWN",tblLoans[[#This Row],[MYR_verdict]]="UNKNOWN")),1,0) -> 0 | AH2: =IF(OR(_xlfn.ISFORMULA(tblLoans[[#This Row],[loan_id]]),_xlfn.ISFORMULA(tblLoans[[#This Row],[borrower_reference]]),_xlfn.ISFORMULA(tblLoans[[#This Row],[year_loan_made]]),_xlfn.ISFORMULA(tblLoans[[#This Row],[written_agreement]]),_xlfn.ISFORMULA(tblLoans[[#This Row],[terms_in_place_before_lodgment_day]]),_xlfn.ISFORMULA(tblLoans[[#This Row],[maximum_term_years]]),_xlfn.ISFORMULA(tblLoans[[#This Row],[secured_by_registered_mortgage_over_real_property]]),_xlfn.ISFORMULA(tblLoans[[#This Row],[security_coverage_at_first_made]]),_xlfn.ISFORMULA(tblLoans[[#This Row],[interest_rate_for_years_after_year_loan_made]]),_xlfn.ISFORMULA(tblLoans[[#This Row],[amalgamated_loan_unpaid_at_end_of_previous_year]]),_xlfn.ISFORMULA(tblLoans[[#This Row],[remaining_term_years]]),_xlfn.ISFORMULA(tblLoans[[#This Row],[payments_applied_during_the_year]]),_xlfn.ISFORMULA(tblLoans[[#This Row],[out_of_scope_reason]]),_xlfn.ISFORMULA(tblLoans[[#This Row],[year_of_income_being_tested]])),1,0) -> 0 | AI2: =IF(TRIM(tblLoans[[#This Row],[out_of_scope_reason]]&"")<>"","",TRIM(IF(OR(AND(NOT(OR(LOWER(TRIM(tblLoans[[#This Row],[Year_made_text]]&""))={"","-","?","n/a","na","unk","unknown"})),NOT(IFERROR(AND(LEN(tblLoans[[#This Row],[Year_made_text]])=7,MID(tblLoans[[#This Row],[Year_made_text]],5,1)="-",ISNUMBER(VALUE(MID(tblLoans[[#This Row],[Year_made_text]],1,1))),ISNUMBER(VALUE(MID(tblLoans[[#This Row],[Year_made_text]],2,1))),ISNUMBER(VALUE(MID(tblLoans[[#This Row],[Year_made_text]],3,1))),ISNUMBER(VALUE(MID(tblLoans[[#This Row],[Year_made_text]],4,1))),ISNUMBER(VALUE(MID(tblLoans[[#This Row],[Year_made_text]],6,1))),ISNUMBER(VALUE(MID(tblLoans[[#This Row],[Year_made_text]],7,1))),VALUE(RIGHT(tblLoans[[#This Row],[Year_made_text]],2))=MOD(VALUE(LEFT(tblLoans[[#This Row],[Year_made_text]],4))+1,100),VALUE(LEFT(tblLoans[[#This Row],[Year_made_text]],4))>=1900,VALUE(LEFT(tblLoans[[#This Row],[Year_made_text]],4))<=2100),FALSE))),AND(tblLoans[[#This Row],[Status]]="REVIEWED",AND(NOT(OR(LOWER(TRIM(tblLoans[[#This Row],[Year_tested_text]]&""))={"","-","?","n/a","na","unk","unknown"})),NOT(IFERROR(AND(LEN(tblLoans[[#This Row],[Year_tested_text]])=7,MID(tblLoans[[#This Row],[Year_tested_text]],5,1)="-",ISNUMBER(VALUE(MID(tblLoans[[#This Row],[Year_tested_text]],1,1))),ISNUMBER(VALUE(MID(tblLoans[[#This Row],[Year_tested_text]],2,1))),ISNUMBER(VALUE(MID(tblLoans[[#This Row],[Year_tested_text]],3,1))),ISNUMBER(VALUE(MID(tblLoans[[#This Row],[Year_tested_text]],4,1))),ISNUMBER(VALUE(MID(tblLoans[[#This Row],[Year_tested_text]],6,1))),ISNUMBER(VALUE(MID(tblLoans[[#This Row],[Year_tested_text]],7,1))),VALUE(RIGHT(tblLoans[[#This Row],[Year_tested_text]],2))=MOD(VALUE(LEFT(tblLoans[[#This Row],[Year_tested_text]],4))+1,100),VALUE(LEFT(tblLoans[[#This Row],[Year_tested_text]],4))>=1900,VALUE(LEFT(tblLoans[[#This Row],[Year_tested_text]],4))<=2100),FALSE))))),"year label ","")&IF(tblLoans[[#This Row],[Status]]<>"REVIEWED","",IF(OR(AND(NOT(OR(LOWER(TRIM(tblLoans[[#This Row],[written_agreement]]&""))={"","-","?","n/a","na","unk","unknown"})),NOT(OR(LOWER(TRIM(tblLoans[[#This Row],[written_agreement]]&""))={"0","1","f","false","n","no","t","true","y","yes"}))),AND(NOT(OR(LOWER(TRIM(tblLoans[[#This Row],[terms_in_place_before_lodgment_day]]&""))={"","-","?","n/a","na","unk","unknown"})),NOT(OR(LOWER(TRIM(tblLoans[[#This Row],[terms_in_place_before_lodgment_day]]&""))={"0","1","f","false","n","no","t","true","y","yes"}))),AND(NOT(OR(LOWER(TRIM(tblLoans[[#This Row],[secured_by_registered_mortgage_over_real_property]]&""))={"","-","?","n/a","na","unk","unknown"})),NOT(OR(LOWER(TRIM(tblLoans[[#This Row],[secured_by_registered_mortgage_over_real_property]]&""))={"0","1","f","false","n","no","t","true","y","yes"})))),"true/false/unknown ","")&IF(OR(AND(NOT(OR(LOWER(TRIM(tblLoans[[#This Row],[maximum_term_years]]&""))={"","-","?","n/a","na","unk","unknown"})),OR(NOT(ISNUMBER(tblLoans[[#This Row],[maximum_term_years]])),AND(ISNUMBER(tblLoans[[#This Row],[maximum_term_years]]),OR(tblLoans[[#This Row],[maximum_term_years]]<0)))),AND(NOT(OR(LOWER(TRIM(tblLoans[[#This Row],[security_coverage_at_first_made]]&""))={"","-","?","n/a","na","unk","unknown"})),OR(NOT(ISNUMBER(tblLoans[[#This Row],[security_coverage_at_first_made]])),AND(ISNUMBER(tblLoans[[#This Row],[security_coverage_at_first_made]]),OR(tblLoans[[#This Row],[security_coverage_at_first_made]]<0)))),AND(NOT(OR(LOWER(TRIM(tblLoans[[#This Row],[interest_rate_for_years_after_year_loan_made]]&""))={"","-","?","n/a","na","unk","unknown"})),OR(NOT(ISNUMBER(tblLoans[[#This Row],[interest_rate_for_years_after_year_loan_made]])),AND(ISNUMBER(tblLoans[[#This Row],[interest_rate_for_years_after_year_loan_made]]),OR(tblLoans[[#This Row],[interest_rate_for_years_after_year_loan_made]]<0,tblLoans[[#This Row],[interest_rate_for_years_after_year_loan_made]]>1)))),AND(NOT(OR(LOWER(TRIM(tblLoans[[#This Row],[amalgamated_loan_unpaid_at_end_of_previous_year]]&""))={"","-","?","n/a","na","unk","unknown"})),OR(NOT(ISNUMBER(tblLoans[[#This Row],[amalgamated_loan_unpaid_at_end_of_previous_year]])),AND(ISNUMBER(tblLoans[[#This Row],[amalgamated_loan_unpaid_at_end_of_previous_year]]),OR(tblLoans[[#This Row],[amalgamated_loan_unpaid_at_end_of_previous_year]]<0,ROUND(N(tblLoans[[#This Row],[amalgamated_loan_unpaid_at_end_of_previous_year]]),2)<>N(tblLoans[[#This Row],[amalgamated_loan_unpaid_at_end_of_previous_year]]),N(tblLoans[[#This Row],[amalgamated_loan_unpaid_at_end_of_previous_year]])>1000000000000)))),AND(NOT(OR(LOWER(TRIM(tblLoans[[#This Row],[remaining_term_years]]&""))={"","-","?","n/a","na","unk","unknown"})),OR(NOT(ISNUMBER(tblLoans[[#This Row],[remaining_term_years]])),AND(ISNUMBER(tblLoans[[#This Row],[remaining_term_years]]),OR(tblLoans[[#This Row],[remaining_term_years]]<0)))),AND(NOT(OR(LOWER(TRIM(tblLoans[[#This Row],[payments_applied_during_the_year]]&""))={"","-","?","n/a","na","unk","unknown"})),OR(NOT(ISNUMBER(tblLoans[[#This Row],[payments_applied_during_the_year]])),AND(ISNUMBER(tblLoans[[#This Row],[payments_applied_during_the_year]]),OR(tblLoans[[#This Row],[payments_applied_during_the_year]]<0,ROUND(N(tblLoans[[#This Row],[payments_applied_during_the_year]]),2)<>N(tblLoans[[#This Row],[payments_applied_during_the_year]]),N(tblLoans[[#This Row],[payments_applied_during_the_year]])>1000000000000))))),"number ","")))) | AJ2: =IF(SUMPRODUCT((tblLoans[[#This Row],[loan_id]]&""={"L-101","L-102","L-103","L-104","L-105","L-106","L-107","L-108"})*(tblLoans[[#This Row],[Year_made_text]]&""={"2023-24","2022-23","2021-22","2024-25","2019-20","2020-21","2023-24","1996-97"}))>0,1,0) -> 1 | AK2: =TRIM(SUBSTITUTE(SUBSTITUTE(SUBSTITUTE(SUBSTITUTE(SUBSTITUTE(SUBSTITUTE(SUBSTITUTE(SUBSTITUTE(SUBSTITUTE(SUBSTITUTE(SUBSTITUTE(SUBSTITUTE(SUBSTITUTE(SUBSTITUTE(SUBSTITUTE(SUBSTITUTE(SUBSTITUTE(SUBSTITUTE(SUBSTITUTE(SUBSTITUTE(SUBSTITUTE(SUBSTITUTE(SUBSTITUTE(SUBSTITUTE(SUBSTITUTE(SUBSTITUTE(SUBSTITUTE(SUBSTITUTE(tblLoans[[#This Row],[year_loan_made]]&"",_xlfn.UNICHAR(9)," "),_xlfn.UNICHAR(10)," "),_xlfn.UNICHAR(11)," "),_xlfn.UNICHAR(12)," "),_xlfn.UNICHAR(13)," "),_xlfn.UNICHAR(28)," "),_xlfn.UNICHAR(29)," "),_xlfn.UNICHAR(30)," "),_xlfn.UNICHAR(31)," "),_xlfn.UNICHAR(133)," "),_xlfn.UNICHAR(160)," "),_xlfn.UNICHAR(5760)," "),_xlfn.UNICHAR(8192)," "),_xlfn.UNICHAR(8193)," "),_xlfn.UNICHAR(8194)," "),_xlfn.UNICHAR(8195)," "),_xlfn.UNICHAR(8196)," "),_xlfn.UNICHAR(8197)," "),_xlfn.UNICHAR(8198)," "),_xlfn.UNICHAR(8199)," "),_xlfn.UNICHAR(8200)," "),_xlfn.UNICHAR(8201)," "),_xlfn.UNICHAR(8202)," "),_xlfn.UNICHAR(8232)," "),_xlfn.UNICHAR(8233)," "),_xlfn.UNICHAR(8239)," "),_xlfn.UNICHAR(8287)," "),_xlfn.UNICHAR(12288)," ")) -> 2023-24 | AL2: =TRIM(SUBSTITUTE(SUBSTITUTE(SUBSTITUTE(SUBSTITUTE(SUBSTITUTE(SUBSTITUTE(SUBSTITUTE(SUBSTITUTE(SUBSTITUTE(SUBSTITUTE(SUBSTITUTE(SUBSTITUTE(SUBSTITUTE(SUBSTITUTE(SUBSTITUTE(SUBSTITUTE(SUBSTITUTE(SUBSTITUTE(SUBSTITUTE(SUBSTITUTE(SUBSTITUTE(SUBSTITUTE(SUBSTITUTE(SUBSTITUTE(SUBSTITUTE(SUBSTITUTE(SUBSTITUTE(SUBSTITUTE(tblLoans[[#This Row],[year_of_income_being_tested]]&"",_xlfn.UNICHAR(9)," "),_xlfn.UNICHAR(10)," "),_xlfn.UNICHAR(11)," "),_xlfn.UNICHAR(12)," "),_xlfn.UNICHAR(13)," "),_xlfn.UNICHAR(28)," "),_xlfn.UNICHAR(29)," "),_xlfn.UNICHAR(30)," "),_xlfn.UNICHAR(31)," "),_xlfn.UNICHAR(133)," "),_xlfn.UNICHAR(160)," "),_xlfn.UNICHAR(5760)," "),_xlfn.UNICHAR(8192)," "),_xlfn.UNICHAR(8193)," "),_xlfn.UNICHAR(8194)," "),_xlfn.UNICHAR(8195)," "),_xlfn.UNICHAR(8196)," "),_xlfn.UNICHAR(8197)," "),_xlfn.UNICHAR(8198)," "),_xlfn.UNICHAR(8199)," "),_xlfn.UNICHAR(8200)," "),_xlfn.UNICHAR(8201)," "),_xlfn.UNICHAR(8202)," "),_xlfn.UNICHAR(8232)," "),_xlfn.UNICHAR(8233)," "),_xlfn.UNICHAR(8239)," "),_xlfn.UNICHAR(8287)," "),_xlfn.UNICHAR(12288)," "))
A3: L-102 | B3: SYN-ASSOCIATE-B | C3: 2022-23 | D3: true | E3: true | F3: 7 | G3: false | H3: unknown | I3: 0.04 | J3: 90000 | K3: 4 | L3: 20000 | O3: =IF(TRIM(tblLoans[[#This Row],[out_of_scope_reason]]&"")<>"","SKIPPED",IF(IFERROR(VALUE(LEFT(tblLoans[[#This Row],[Year_made_text]],4))<1998,FALSE),"SKIPPED","REVIEWED")) -> REVIEWED | P3: =IF(OR(LOWER(TRIM(tblLoans[[#This Row],[Year_tested_text]]&""))={"","-","?","n/a","na","unk","unknown"}),tblLoans[[#This Row],[Year_made_text]],tblLoans[[#This Row],[Year_tested_text]]) -> 2022-23 | Q3: =IFERROR(INDEX(tblRates[rate],MATCH(tblLoans[[#This Row],[Floor_year]],tblRates[year_of_income],0)),"") -> 0.0477 | R3: =IF(OR(LOWER(TRIM(tblLoans[[#This Row],[written_agreement]]&""))={"","-","?","n/a","na","unk","unknown"}),"UNKNOWN",IF(OR(LOWER(TRIM(tblLoans[[#This Row],[written_agreement]]&""))={"1","t","true","y","yes"}),"PASS",IF(OR(LOWER(TRIM(tblLoans[[#This Row],[written_agreement]]&""))={"0","f","false","n","no"}),"FAIL","UNKNOWN"))) -> PASS | S3: =IF(OR(LOWER(TRIM(tblLoans[[#This Row],[terms_in_place_before_lodgment_day]]&""))={"","-","?","n/a","na","unk","unknown"}),"UNKNOWN",IF(OR(LOWER(TRIM(tblLoans[[#This Row],[terms_in_place_before_lodgment_day]]&""))={"1","t","true","y","yes"}),"PASS",IF(OR(LOWER(TRIM(tblLoans[[#This Row],[terms_in_place_before_lodgment_day]]&""))={"0","f","false","n","no"}),"FAIL","UNKNOWN"))) -> PASS | T3: =IF(NOT(ISNUMBER(tblLoans[[#This Row],[interest_rate_for_years_after_year_loan_made]])),"UNKNOWN",IF(tblLoans[[#This Row],[Floor_rate]]="","UNKNOWN",IF(tblLoans[[#This Row],[interest_rate_for_years_after_year_loan_made]]>=tblLoans[[#This Row],[Floor_rate]],"PASS","FAIL"))) -> FAIL | U3: =IF(OR(LOWER(TRIM(tblLoans[[#This Row],[secured_by_registered_mortgage_over_real_property]]&""))={"","-","?","n/a","na","unk","unknown"}),"UNKNOWN",IF(OR(LOWER(TRIM(tblLoans[[#This Row],[secured_by_registered_mortgage_over_real_property]]&""))={"1","t","true","y","yes"}),"PASS",IF(OR(LOWER(TRIM(tblLoans[[#This Row],[secured_by_registered_mortgage_over_real_property]]&""))={"0","f","false","n","no"}),"FAIL","UNKNOWN"))) -> FAIL | V3: =IF(tblLoans[[#This Row],[Limb_secured]]="FAIL",7,IF(tblLoans[[#This Row],[Limb_secured]]="PASS",IF(ISNUMBER(tblLoans[[#This Row],[security_coverage_at_first_made]]),IF(tblLoans[[#This Row],[security_coverage_at_first_made]]>=1.1,25,7),""),"")) -> 7 | W3: =IF(NOT(ISNUMBER(tblLoans[[#This Row],[maximum_term_years]])),"UNKNOWN",IF(tblLoans[[#This Row],[Allowed_term_raw]]="",IF(tblLoans[[#This Row],[maximum_term_years]]<=7,"PASS","UNKNOWN"),IF(tblLoans[[#This Row],[maximum_term_years]]<=tblLoans[[#This Row],[Allowed_term_raw]],"PASS","FAIL"))) -> PASS | X3: =IF(tblLoans[[#This Row],[Status]]="SKIPPED","",IF(OR(LOWER(TRIM(tblLoans[[#This Row],[Floor_year]]&""))={"","-","?","n/a","na","unk","unknown"}),"UNKNOWN",IF(OR(tblLoans[[#This Row],[Limb_a_written]]="FAIL",tblLoans[[#This Row],[Limb_lodgment]]="FAIL",tblLoans[[#This Row],[Limb_b_rate]]="FAIL",tblLoans[[#This Row],[Limb_c_term]]="FAIL"),"NOT_COMPLYING",IF(OR(tblLoans[[#This Row],[Limb_a_written]]="UNKNOWN",tblLoans[[#This Row],[Limb_lodgment]]="UNKNOWN",tblLoans[[#This Row],[Limb_b_rate]]="UNKNOWN",tblLoans[[#This Row],[Limb_c_term]]="UNKNOWN"),"UNKNOWN","COMPLYING")))) -> NOT_COMPLYING | Y3: =IF(OR(tblLoans[[#This Row],[Status]]="SKIPPED",OR(LOWER(TRIM(tblLoans[[#This Row],[Floor_year]]&""))={"","-","?","n/a","na","unk","unknown"})),"",IF(tblLoans[[#This Row],[Allowed_term_raw]]<>"",tblLoans[[#This Row],[Allowed_term_raw]],IF(AND(ISNUMBER(tblLoans[[#This Row],[maximum_term_years]]),tblLoans[[#This Row],[maximum_term_years]]<=7),7,""))) -> 7 | Z3: =IF(tblLoans[[#This Row],[Status]]="SKIPPED","",IF(ISNUMBER(tblLoans[[#This Row],[remaining_term_years]]),ROUNDUP(tblLoans[[#This Row],[remaining_term_years]],0),"")) -> 4 | AA3: =IF(AND(ISNUMBER(tblLoans[[#This Row],[amalgamated_loan_unpaid_at_end_of_previous_year]]),ISNUMBER(Summary!$B$3),Summary!$B$3>0,ISNUMBER(tblLoans[[#This Row],[Term_used]]),tblLoans[[#This Row],[Term_used]]>0),ROUND(tblLoans[[#This Row],[amalgamated_loan_unpaid_at_end_of_previous_year]]*Summary!$B$3/(1-(1/(1+Summary!$B$3))^tblLoans[[#This Row],[Term_used]]),2),"") -> 27640.06 | AB3: =IF(tblLoans[[#This Row],[Status]]="SKIPPED","",IF(OR(tblLoans[[#This Row],[Gate_verdict]]<>"COMPLYING",AND(NOT(OR(LOWER(TRIM(tblLoans[[#This Row],[Year_made_text]]&""))={"","-","?","n/a","na","unk","unknown"})),tblLoans[[#This Row],[Floor_year]]<>tblLoans[[#This Row],[Year_made_text]]),tblLoans[[#This Row],[Year_made_text]]=Summary!$B$2,IFERROR(VALUE(LEFT(tblLoans[[#This Row],[Year_made_text]],4))>Summary!$B$4,FALSE),AND(ISNUMBER(tblLoans[[#This Row],[Term_used]]),tblLoans[[#This Row],[Term_used]]<=0),AND(ISNUMBER(Summary!$B$3),Summary!$B$3<=0)),"REFUSED",IF(OR(OR(LOWER(TRIM(tblLoans[[#This Row],[Year_made_text]]&""))={"","-","?","n/a","na","unk","unknown"}),NOT(ISNUMBER(Summary!$B$3)),NOT(ISNUMBER(tblLoans[[#This Row],[amalgamated_loan_unpaid_at_end_of_previous_year]])),NOT(ISNUMBER(tblLoans[[#This Row],[payments_applied_during_the_year]])),NOT(ISNUMBER(tblLoans[[#This Row],[Term_used]]))),"UNKNOWN",IF(tblLoans[[#This Row],[MYR_raw]]-ROUND(tblLoans[[#This Row],[payments_applied_during_the_year]],2)<=0,"MYR_MET","MYR_SHORT")))) -> REFUSED | AC3: =IF(tblLoans[[#This Row],[MYR_verdict]]="REFUSED",IF(tblLoans[[#This Row],[Gate_verdict]]<>"COMPLYING","s 109N gate is "&tblLoans[[#This Row],[Gate_verdict]]&", so s 109E produces no repayment figure",IF(tblLoans[[#This Row],[Floor_year]]<>tblLoans[[#This Row],[Year_made_text]],"gate benchmark year differs from year_loan_made",IF(tblLoans[[#This Row],[Year_made_text]]=Summary!$B$2,"year of income is the year the loan was made (s 109E(1)(a), s 109P)",IF(IFERROR(VALUE(LEFT(tblLoans[[#This Row],[Year_made_text]],4))>Summary!$B$4,FALSE),"loan made after the year of income",IF(AND(ISNUMBER(tblLoans[[#This Row],[Term_used]]),tblLoans[[#This Row],[Term_used]]<=0),"nil remaining term under s 109E(6)","nil benchmark rate"))))),IF(tblLoans[[#This Row],[MYR_verdict]]="UNKNOWN",IF(OR(LOWER(TRIM(tblLoans[[#This Row],[Year_made_text]]&""))={"","-","?","n/a","na","unk","unknown"}),"year_loan_made not established",IF(NOT(ISNUMBER(Summary!$B$3)),"no reviewed benchmark rate for the year of income",IF(NOT(ISNUMBER(tblLoans[[#This Row],[amalgamated_loan_unpaid_at_end_of_previous_year]])),"unpaid balance at end of previous year not established",IF(NOT(ISNUMBER(tblLoans[[#This Row],[payments_applied_during_the_year]])),"payments applied not established","remaining term not established")))),"")) -> s 109N gate is NOT_COMPLYING, so s 109E produces no repayment figure | AD3: =IF(OR(tblLoans[[#This Row],[MYR_verdict]]="MYR_MET",tblLoans[[#This Row],[MYR_verdict]]="MYR_SHORT"),tblLoans[[#This Row],[MYR_raw]],"") | AE3: =IF(OR(tblLoans[[#This Row],[MYR_verdict]]="MYR_MET",tblLoans[[#This Row],[MYR_verdict]]="MYR_SHORT"),MAX(0,ROUND(tblLoans[[#This Row],[MYR_raw]]-ROUND(tblLoans[[#This Row],[payments_applied_during_the_year]],2),2)),"") | AF3: =IF(tblLoans[[#This Row],[MYR_verdict]]="MYR_SHORT",tblLoans[[#This Row],[Shortfall]],"") | AG3: =IF(AND(tblLoans[[#This Row],[Status]]="REVIEWED",OR(tblLoans[[#This Row],[Gate_verdict]]="UNKNOWN",tblLoans[[#This Row],[MYR_verdict]]="UNKNOWN")),1,0) -> 0 | AH3: =IF(OR(_xlfn.ISFORMULA(tblLoans[[#This Row],[loan_id]]),_xlfn.ISFORMULA(tblLoans[[#This Row],[borrower_reference]]),_xlfn.ISFORMULA(tblLoans[[#This Row],[year_loan_made]]),_xlfn.ISFORMULA(tblLoans[[#This Row],[written_agreement]]),_xlfn.ISFORMULA(tblLoans[[#This Row],[terms_in_place_before_lodgment_day]]),_xlfn.ISFORMULA(tblLoans[[#This Row],[maximum_term_years]]),_xlfn.ISFORMULA(tblLoans[[#This Row],[secured_by_registered_mortgage_over_real_property]]),_xlfn.ISFORMULA(tblLoans[[#This Row],[security_coverage_at_first_made]]),_xlfn.ISFORMULA(tblLoans[[#This Row],[interest_rate_for_years_after_year_loan_made]]),_xlfn.ISFORMULA(tblLoans[[#This Row],[amalgamated_loan_unpaid_at_end_of_previous_year]]),_xlfn.ISFORMULA(tblLoans[[#This Row],[remaining_term_years]]),_xlfn.ISFORMULA(tblLoans[[#This Row],[payments_applied_during_the_year]]),_xlfn.ISFORMULA(tblLoans[[#This Row],[out_of_scope_reason]]),_xlfn.ISFORMULA(tblLoans[[#This Row],[year_of_income_being_tested]])),1,0) -> 0 | AI3: =IF(TRIM(tblLoans[[#This Row],[out_of_scope_reason]]&"")<>"","",TRIM(IF(OR(AND(NOT(OR(LOWER(TRIM(tblLoans[[#This Row],[Year_made_text]]&""))={"","-","?","n/a","na","unk","unknown"})),NOT(IFERROR(AND(LEN(tblLoans[[#This Row],[Year_made_text]])=7,MID(tblLoans[[#This Row],[Year_made_text]],5,1)="-",ISNUMBER(VALUE(MID(tblLoans[[#This Row],[Year_made_text]],1,1))),ISNUMBER(VALUE(MID(tblLoans[[#This Row],[Year_made_text]],2,1))),ISNUMBER(VALUE(MID(tblLoans[[#This Row],[Year_made_text]],3,1))),ISNUMBER(VALUE(MID(tblLoans[[#This Row],[Year_made_text]],4,1))),ISNUMBER(VALUE(MID(tblLoans[[#This Row],[Year_made_text]],6,1))),ISNUMBER(VALUE(MID(tblLoans[[#This Row],[Year_made_text]],7,1))),VALUE(RIGHT(tblLoans[[#This Row],[Year_made_text]],2))=MOD(VALUE(LEFT(tblLoans[[#This Row],[Year_made_text]],4))+1,100),VALUE(LEFT(tblLoans[[#This Row],[Year_made_text]],4))>=1900,VALUE(LEFT(tblLoans[[#This Row],[Year_made_text]],4))<=2100),FALSE))),AND(tblLoans[[#This Row],[Status]]="REVIEWED",AND(NOT(OR(LOWER(TRIM(tblLoans[[#This Row],[Year_tested_text]]&""))={"","-","?","n/a","na","unk","unknown"})),NOT(IFERROR(AND(LEN(tblLoans[[#This Row],[Year_tested_text]])=7,MID(tblLoans[[#This Row],[Year_tested_text]],5,1)="-",ISNUMBER(VALUE(MID(tblLoans[[#This Row],[Year_tested_text]],1,1))),ISNUMBER(VALUE(MID(tblLoans[[#This Row],[Year_tested_text]],2,1))),ISNUMBER(VALUE(MID(tblLoans[[#This Row],[Year_tested_text]],3,1))),ISNUMBER(VALUE(MID(tblLoans[[#This Row],[Year_tested_text]],4,1))),ISNUMBER(VALUE(MID(tblLoans[[#This Row],[Year_tested_text]],6,1))),ISNUMBER(VALUE(MID(tblLoans[[#This Row],[Year_tested_text]],7,1))),VALUE(RIGHT(tblLoans[[#This Row],[Year_tested_text]],2))=MOD(VALUE(LEFT(tblLoans[[#This Row],[Year_tested_text]],4))+1,100),VALUE(LEFT(tblLoans[[#This Row],[Year_tested_text]],4))>=1900,VALUE(LEFT(tblLoans[[#This Row],[Year_tested_text]],4))<=2100),FALSE))))),"year label ","")&IF(tblLoans[[#This Row],[Status]]<>"REVIEWED","",IF(OR(AND(NOT(OR(LOWER(TRIM(tblLoans[[#This Row],[written_agreement]]&""))={"","-","?","n/a","na","unk","unknown"})),NOT(OR(LOWER(TRIM(tblLoans[[#This Row],[written_agreement]]&""))={"0","1","f","false","n","no","t","true","y","yes"}))),AND(NOT(OR(LOWER(TRIM(tblLoans[[#This Row],[terms_in_place_before_lodgment_day]]&""))={"","-","?","n/a","na","unk","unknown"})),NOT(OR(LOWER(TRIM(tblLoans[[#This Row],[terms_in_place_before_lodgment_day]]&""))={"0","1","f","false","n","no","t","true","y","yes"}))),AND(NOT(OR(LOWER(TRIM(tblLoans[[#This Row],[secured_by_registered_mortgage_over_real_property]]&""))={"","-","?","n/a","na","unk","unknown"})),NOT(OR(LOWER(TRIM(tblLoans[[#This Row],[secured_by_registered_mortgage_over_real_property]]&""))={"0","1","f","false","n","no","t","true","y","yes"})))),"true/false/unknown ","")&IF(OR(AND(NOT(OR(LOWER(TRIM(tblLoans[[#This Row],[maximum_term_years]]&""))={"","-","?","n/a","na","unk","unknown"})),OR(NOT(ISNUMBER(tblLoans[[#This Row],[maximum_term_years]])),AND(ISNUMBER(tblLoans[[#This Row],[maximum_term_years]]),OR(tblLoans[[#This Row],[maximum_term_years]]<0)))),AND(NOT(OR(LOWER(TRIM(tblLoans[[#This Row],[security_coverage_at_first_made]]&""))={"","-","?","n/a","na","unk","unknown"})),OR(NOT(ISNUMBER(tblLoans[[#This Row],[security_coverage_at_first_made]])),AND(ISNUMBER(tblLoans[[#This Row],[security_coverage_at_first_made]]),OR(tblLoans[[#This Row],[security_coverage_at_first_made]]<0)))),AND(NOT(OR(LOWER(TRIM(tblLoans[[#This Row],[interest_rate_for_years_after_year_loan_made]]&""))={"","-","?","n/a","na","unk","unknown"})),OR(NOT(ISNUMBER(tblLoans[[#This Row],[interest_rate_for_years_after_year_loan_made]])),AND(ISNUMBER(tblLoans[[#This Row],[interest_rate_for_years_after_year_loan_made]]),OR(tblLoans[[#This Row],[interest_rate_for_years_after_year_loan_made]]<0,tblLoans[[#This Row],[interest_rate_for_years_after_year_loan_made]]>1)))),AND(NOT(OR(LOWER(TRIM(tblLoans[[#This Row],[amalgamated_loan_unpaid_at_end_of_previous_year]]&""))={"","-","?","n/a","na","unk","unknown"})),OR(NOT(ISNUMBER(tblLoans[[#This Row],[amalgamated_loan_unpaid_at_end_of_previous_year]])),AND(ISNUMBER(tblLoans[[#This Row],[amalgamated_loan_unpaid_at_end_of_previous_year]]),OR(tblLoans[[#This Row],[amalgamated_loan_unpaid_at_end_of_previous_year]]<0,ROUND(N(tblLoans[[#This Row],[amalgamated_loan_unpaid_at_end_of_previous_year]]),2)<>N(tblLoans[[#This Row],[amalgamated_loan_unpaid_at_end_of_previous_year]]),N(tblLoans[[#This Row],[amalgamated_loan_unpaid_at_end_of_previous_year]])>1000000000000)))),AND(NOT(OR(LOWER(TRIM(tblLoans[[#This Row],[remaining_term_years]]&""))={"","-","?","n/a","na","unk","unknown"})),OR(NOT(ISNUMBER(tblLoans[[#This Row],[remaining_term_years]])),AND(ISNUMBER(tblLoans[[#This Row],[remaining_term_years]]),OR(tblLoans[[#This Row],[remaining_term_years]]<0)))),AND(NOT(OR(LOWER(TRIM(tblLoans[[#This Row],[payments_applied_during_the_year]]&""))={"","-","?","n/a","na","unk","unknown"})),OR(NOT(ISNUMBER(tblLoans[[#This Row],[payments_applied_during_the_year]])),AND(ISNUMBER(tblLoans[[#This Row],[payments_applied_during_the_year]]),OR(tblLoans[[#This Row],[payments_applied_during_the_year]]<0,ROUND(N(tblLoans[[#This Row],[payments_applied_during_the_year]]),2)<>N(tblLoans[[#This Row],[payments_applied_during_the_year]]),N(tblLoans[[#This Row],[payments_applied_during_the_year]])>1000000000000))))),"number ","")))) | AJ3: =IF(SUMPRODUCT((tblLoans[[#This Row],[loan_id]]&""={"L-101","L-102","L-103","L-104","L-105","L-106","L-107","L-108"})*(tblLoans[[#This Row],[Year_made_text]]&""={"2023-24","2022-23","2021-22","2024-25","2019-20","2020-21","2023-24","1996-97"}))>0,1,0) -> 1 | AK3: =TRIM(SUBSTITUTE(SUBSTITUTE(SUBSTITUTE(SUBSTITUTE(SUBSTITUTE(SUBSTITUTE(SUBSTITUTE(SUBSTITUTE(SUBSTITUTE(SUBSTITUTE(SUBSTITUTE(SUBSTITUTE(SUBSTITUTE(SUBSTITUTE(SUBSTITUTE(SUBSTITUTE(SUBSTITUTE(SUBSTITUTE(SUBSTITUTE(SUBSTITUTE(SUBSTITUTE(SUBSTITUTE(SUBSTITUTE(SUBSTITUTE(SUBSTITUTE(SUBSTITUTE(SUBSTITUTE(SUBSTITUTE(tblLoans[[#This Row],[year_loan_made]]&"",_xlfn.UNICHAR(9)," "),_xlfn.UNICHAR(10)," "),_xlfn.UNICHAR(11)," "),_xlfn.UNICHAR(12)," "),_xlfn.UNICHAR(13)," "),_xlfn.UNICHAR(28)," "),_xlfn.UNICHAR(29)," "),_xlfn.UNICHAR(30)," "),_xlfn.UNICHAR(31)," "),_xlfn.UNICHAR(133)," "),_xlfn.UNICHAR(160)," "),_xlfn.UNICHAR(5760)," "),_xlfn.UNICHAR(8192)," "),_xlfn.UNICHAR(8193)," "),_xlfn.UNICHAR(8194)," "),_xlfn.UNICHAR(8195)," "),_xlfn.UNICHAR(8196)," "),_xlfn.UNICHAR(8197)," "),_xlfn.UNICHAR(8198)," "),_xlfn.UNICHAR(8199)," "),_xlfn.UNICHAR(8200)," "),_xlfn.UNICHAR(8201)," "),_xlfn.UNICHAR(8202)," "),_xlfn.UNICHAR(8232)," "),_xlfn.UNICHAR(8233)," "),_xlfn.UNICHAR(8239)," "),_xlfn.UNICHAR(8287)," "),_xlfn.UNICHAR(12288)," ")) -> 2022-23 | AL3: =TRIM(SUBSTITUTE(SUBSTITUTE(SUBSTITUTE(SUBSTITUTE(SUBSTITUTE(SUBSTITUTE(SUBSTITUTE(SUBSTITUTE(SUBSTITUTE(SUBSTITUTE(SUBSTITUTE(SUBSTITUTE(SUBSTITUTE(SUBSTITUTE(SUBSTITUTE(SUBSTITUTE(SUBSTITUTE(SUBSTITUTE(SUBSTITUTE(SUBSTITUTE(SUBSTITUTE(SUBSTITUTE(SUBSTITUTE(SUBSTITUTE(SUBSTITUTE(SUBSTITUTE(SUBSTITUTE(SUBSTITUTE(tblLoans[[#This Row],[year_of_income_being_tested]]&"",_xlfn.UNICHAR(9)," "),_xlfn.UNICHAR(10)," "),_xlfn.UNICHAR(11)," "),_xlfn.UNICHAR(12)," "),_xlfn.UNICHAR(13)," "),_xlfn.UNICHAR(28)," "),_xlfn.UNICHAR(29)," "),_xlfn.UNICHAR(30)," "),_xlfn.UNICHAR(31)," "),_xlfn.UNICHAR(133)," "),_xlfn.UNICHAR(160)," "),_xlfn.UNICHAR(5760)," "),_xlfn.UNICHAR(8192)," "),_xlfn.UNICHAR(8193)," "),_xlfn.UNICHAR(8194)," "),_xlfn.UNICHAR(8195)," "),_xlfn.UNICHAR(8196)," "),_xlfn.UNICHAR(8197)," "),_xlfn.UNICHAR(8198)," "),_xlfn.UNICHAR(8199)," "),_xlfn.UNICHAR(8200)," "),_xlfn.UNICHAR(8201)," "),_xlfn.UNICHAR(8202)," "),_xlfn.UNICHAR(8232)," "),_xlfn.UNICHAR(8233)," "),_xlfn.UNICHAR(8239)," "),_xlfn.UNICHAR(8287)," "),_xlfn.UNICHAR(12288)," "))
A4: L-103 | B4: SYN-SHAREHOLDER-C | C4: 2021-22 | D4: unknown | E4: true | F4: 7 | G4: false | H4: unknown | I4: 0.0452 | J4: 50000 | K4: 2 | L4: 15000 | O4: =IF(TRIM(tblLoans[[#This Row],[out_of_scope_reason]]&"")<>"","SKIPPED",IF(IFERROR(VALUE(LEFT(tblLoans[[#This Row],[Year_made_text]],4))<1998,FALSE),"SKIPPED","REVIEWED")) -> REVIEWED | P4: =IF(OR(LOWER(TRIM(tblLoans[[#This Row],[Year_tested_text]]&""))={"","-","?","n/a","na","unk","unknown"}),tblLoans[[#This Row],[Year_made_text]],tblLoans[[#This Row],[Year_tested_text]]) -> 2021-22 | Q4: =IFERROR(INDEX(tblRates[rate],MATCH(tblLoans[[#This Row],[Floor_year]],tblRates[year_of_income],0)),"") -> 0.0452 | R4: =IF(OR(LOWER(TRIM(tblLoans[[#This Row],[written_agreement]]&""))={"","-","?","n/a","na","unk","unknown"}),"UNKNOWN",IF(OR(LOWER(TRIM(tblLoans[[#This Row],[written_agreement]]&""))={"1","t","true","y","yes"}),"PASS",IF(OR(LOWER(TRIM(tblLoans[[#This Row],[written_agreement]]&""))={"0","f","false","n","no"}),"FAIL","UNKNOWN"))) -> UNKNOWN | S4: =IF(OR(LOWER(TRIM(tblLoans[[#This Row],[terms_in_place_before_lodgment_day]]&""))={"","-","?","n/a","na","unk","unknown"}),"UNKNOWN",IF(OR(LOWER(TRIM(tblLoans[[#This Row],[terms_in_place_before_lodgment_day]]&""))={"1","t","true","y","yes"}),"PASS",IF(OR(LOWER(TRIM(tblLoans[[#This Row],[terms_in_place_before_lodgment_day]]&""))={"0","f","false","n","no"}),"FAIL","UNKNOWN"))) -> PASS | T4: =IF(NOT(ISNUMBER(tblLoans[[#This Row],[interest_rate_for_years_after_year_loan_made]])),"UNKNOWN",IF(tblLoans[[#This Row],[Floor_rate]]="","UNKNOWN",IF(tblLoans[[#This Row],[interest_rate_for_years_after_year_loan_made]]>=tblLoans[[#This Row],[Floor_rate]],"PASS","FAIL"))) -> PASS | U4: =IF(OR(LOWER(TRIM(tblLoans[[#This Row],[secured_by_registered_mortgage_over_real_property]]&""))={"","-","?","n/a","na","unk","unknown"}),"UNKNOWN",IF(OR(LOWER(TRIM(tblLoans[[#This Row],[secured_by_registered_mortgage_over_real_property]]&""))={"1","t","true","y","yes"}),"PASS",IF(OR(LOWER(TRIM(tblLoans[[#This Row],[secured_by_registered_mortgage_over_real_property]]&""))={"0","f","false","n","no"}),"FAIL","UNKNOWN"))) -> FAIL | V4: =IF(tblLoans[[#This Row],[Limb_secured]]="FAIL",7,IF(tblLoans[[#This Row],[Limb_secured]]="PASS",IF(ISNUMBER(tblLoans[[#This Row],[security_coverage_at_first_made]]),IF(tblLoans[[#This Row],[security_coverage_at_first_made]]>=1.1,25,7),""),"")) -> 7 | W4: =IF(NOT(ISNUMBER(tblLoans[[#This Row],[maximum_term_years]])),"UNKNOWN",IF(tblLoans[[#This Row],[Allowed_term_raw]]="",IF(tblLoans[[#This Row],[maximum_term_years]]<=7,"PASS","UNKNOWN"),IF(tblLoans[[#This Row],[maximum_term_years]]<=tblLoans[[#This Row],[Allowed_term_raw]],"PASS","FAIL"))) -> PASS | X4: =IF(tblLoans[[#This Row],[Status]]="SKIPPED","",IF(OR(LOWER(TRIM(tblLoans[[#This Row],[Floor_year]]&""))={"","-","?","n/a","na","unk","unknown"}),"UNKNOWN",IF(OR(tblLoans[[#This Row],[Limb_a_written]]="FAIL",tblLoans[[#This Row],[Limb_lodgment]]="FAIL",tblLoans[[#This Row],[Limb_b_rate]]="FAIL",tblLoans[[#This Row],[Limb_c_term]]="FAIL"),"NOT_COMPLYING",IF(OR(tblLoans[[#This Row],[Limb_a_written]]="UNKNOWN",tblLoans[[#This Row],[Limb_lodgment]]="UNKNOWN",tblLoans[[#This Row],[Limb_b_rate]]="UNKNOWN",tblLoans[[#This Row],[Limb_c_term]]="UNKNOWN"),"UNKNOWN","COMPLYING")))) -> UNKNOWN | Y4: =IF(OR(tblLoans[[#This Row],[Status]]="SKIPPED",OR(LOWER(TRIM(tblLoans[[#This Row],[Floor_year]]&""))={"","-","?","n/a","na","unk","unknown"})),"",IF(tblLoans[[#This Row],[Allowed_term_raw]]<>"",tblLoans[[#This Row],[Allowed_term_raw]],IF(AND(ISNUMBER(tblLoans[[#This Row],[maximum_term_years]]),tblLoans[[#This Row],[maximum_term_years]]<=7),7,""))) -> 7 | Z4: =IF(tblLoans[[#This Row],[Status]]="SKIPPED","",IF(ISNUMBER(tblLoans[[#This Row],[remaining_term_years]]),ROUNDUP(tblLoans[[#This Row],[remaining_term_years]],0),"")) -> 2 | AA4: =IF(AND(ISNUMBER(tblLoans[[#This Row],[amalgamated_loan_unpaid_at_end_of_previous_year]]),ISNUMBER(Summary!$B$3),Summary!$B$3>0,ISNUMBER(tblLoans[[#This Row],[Term_used]]),tblLoans[[#This Row],[Term_used]]>0),ROUND(tblLoans[[#This Row],[amalgamated_loan_unpaid_at_end_of_previous_year]]*Summary!$B$3/(1-(1/(1+Summary!$B$3))^tblLoans[[#This Row],[Term_used]]),2),"") -> 28334.8 | AB4: =IF(tblLoans[[#This Row],[Status]]="SKIPPED","",IF(OR(tblLoans[[#This Row],[Gate_verdict]]<>"COMPLYING",AND(NOT(OR(LOWER(TRIM(tblLoans[[#This Row],[Year_made_text]]&""))={"","-","?","n/a","na","unk","unknown"})),tblLoans[[#This Row],[Floor_year]]<>tblLoans[[#This Row],[Year_made_text]]),tblLoans[[#This Row],[Year_made_text]]=Summary!$B$2,IFERROR(VALUE(LEFT(tblLoans[[#This Row],[Year_made_text]],4))>Summary!$B$4,FALSE),AND(ISNUMBER(tblLoans[[#This Row],[Term_used]]),tblLoans[[#This Row],[Term_used]]<=0),AND(ISNUMBER(Summary!$B$3),Summary!$B$3<=0)),"REFUSED",IF(OR(OR(LOWER(TRIM(tblLoans[[#This Row],[Year_made_text]]&""))={"","-","?","n/a","na","unk","unknown"}),NOT(ISNUMBER(Summary!$B$3)),NOT(ISNUMBER(tblLoans[[#This Row],[amalgamated_loan_unpaid_at_end_of_previous_year]])),NOT(ISNUMBER(tblLoans[[#This Row],[payments_applied_during_the_year]])),NOT(ISNUMBER(tblLoans[[#This Row],[Term_used]]))),"UNKNOWN",IF(tblLoans[[#This Row],[MYR_raw]]-ROUND(tblLoans[[#This Row],[payments_applied_during_the_year]],2)<=0,"MYR_MET","MYR_SHORT")))) -> REFUSED | AC4: =IF(tblLoans[[#This Row],[MYR_verdict]]="REFUSED",IF(tblLoans[[#This Row],[Gate_verdict]]<>"COMPLYING","s 109N gate is "&tblLoans[[#This Row],[Gate_verdict]]&", so s 109E produces no repayment figure",IF(tblLoans[[#This Row],[Floor_year]]<>tblLoans[[#This Row],[Year_made_text]],"gate benchmark year differs from year_loan_made",IF(tblLoans[[#This Row],[Year_made_text]]=Summary!$B$2,"year of income is the year the loan was made (s 109E(1)(a), s 109P)",IF(IFERROR(VALUE(LEFT(tblLoans[[#This Row],[Year_made_text]],4))>Summary!$B$4,FALSE),"loan made after the year of income",IF(AND(ISNUMBER(tblLoans[[#This Row],[Term_used]]),tblLoans[[#This Row],[Term_used]]<=0),"nil remaining term under s 109E(6)","nil benchmark rate"))))),IF(tblLoans[[#This Row],[MYR_verdict]]="UNKNOWN",IF(OR(LOWER(TRIM(tblLoans[[#This Row],[Year_made_text]]&""))={"","-","?","n/a","na","unk","unknown"}),"year_loan_made not established",IF(NOT(ISNUMBER(Summary!$B$3)),"no reviewed benchmark rate for the year of income",IF(NOT(ISNUMBER(tblLoans[[#This Row],[amalgamated_loan_unpaid_at_end_of_previous_year]])),"unpaid balance at end of previous year not established",IF(NOT(ISNUMBER(tblLoans[[#This Row],[payments_applied_during_the_year]])),"payments applied not established","remaining term not established")))),"")) -> s 109N gate is UNKNOWN, so s 109E produces no repayment figure | AD4: =IF(OR(tblLoans[[#This Row],[MYR_verdict]]="MYR_MET",tblLoans[[#This Row],[MYR_verdict]]="MYR_SHORT"),tblLoans[[#This Row],[MYR_raw]],"") | AE4: =IF(OR(tblLoans[[#This Row],[MYR_verdict]]="MYR_MET",tblLoans[[#This Row],[MYR_verdict]]="MYR_SHORT"),MAX(0,ROUND(tblLoans[[#This Row],[MYR_raw]]-ROUND(tblLoans[[#This Row],[payments_applied_during_the_year]],2),2)),"") | AF4: =IF(tblLoans[[#This Row],[MYR_verdict]]="MYR_SHORT",tblLoans[[#This Row],[Shortfall]],"") | AG4: =IF(AND(tblLoans[[#This Row],[Status]]="REVIEWED",OR(tblLoans[[#This Row],[Gate_verdict]]="UNKNOWN",tblLoans[[#This Row],[MYR_verdict]]="UNKNOWN")),1,0) -> 1 | AH4: =IF(OR(_xlfn.ISFORMULA(tblLoans[[#This Row],[loan_id]]),_xlfn.ISFORMULA(tblLoans[[#This Row],[borrower_reference]]),_xlfn.ISFORMULA(tblLoans[[#This Row],[year_loan_made]]),_xlfn.ISFORMULA(tblLoans[[#This Row],[written_agreement]]),_xlfn.ISFORMULA(tblLoans[[#This Row],[terms_in_place_before_lodgment_day]]),_xlfn.ISFORMULA(tblLoans[[#This Row],[maximum_term_years]]),_xlfn.ISFORMULA(tblLoans[[#This Row],[secured_by_registered_mortgage_over_real_property]]),_xlfn.ISFORMULA(tblLoans[[#This Row],[security_coverage_at_first_made]]),_xlfn.ISFORMULA(tblLoans[[#This Row],[interest_rate_for_years_after_year_loan_made]]),_xlfn.ISFORMULA(tblLoans[[#This Row],[amalgamated_loan_unpaid_at_end_of_previous_year]]),_xlfn.ISFORMULA(tblLoans[[#This Row],[remaining_term_years]]),_xlfn.ISFORMULA(tblLoans[[#This Row],[payments_applied_during_the_year]]),_xlfn.ISFORMULA(tblLoans[[#This Row],[out_of_scope_reason]]),_xlfn.ISFORMULA(tblLoans[[#This Row],[year_of_income_being_tested]])),1,0) -> 0 | AI4: =IF(TRIM(tblLoans[[#This Row],[out_of_scope_reason]]&"")<>"","",TRIM(IF(OR(AND(NOT(OR(LOWER(TRIM(tblLoans[[#This Row],[Year_made_text]]&""))={"","-","?","n/a","na","unk","unknown"})),NOT(IFERROR(AND(LEN(tblLoans[[#This Row],[Year_made_text]])=7,MID(tblLoans[[#This Row],[Year_made_text]],5,1)="-",ISNUMBER(VALUE(MID(tblLoans[[#This Row],[Year_made_text]],1,1))),ISNUMBER(VALUE(MID(tblLoans[[#This Row],[Year_made_text]],2,1))),ISNUMBER(VALUE(MID(tblLoans[[#This Row],[Year_made_text]],3,1))),ISNUMBER(VALUE(MID(tblLoans[[#This Row],[Year_made_text]],4,1))),ISNUMBER(VALUE(MID(tblLoans[[#This Row],[Year_made_text]],6,1))),ISNUMBER(VALUE(MID(tblLoans[[#This Row],[Year_made_text]],7,1))),VALUE(RIGHT(tblLoans[[#This Row],[Year_made_text]],2))=MOD(VALUE(LEFT(tblLoans[[#This Row],[Year_made_text]],4))+1,100),VALUE(LEFT(tblLoans[[#This Row],[Year_made_text]],4))>=1900,VALUE(LEFT(tblLoans[[#This Row],[Year_made_text]],4))<=2100),FALSE))),AND(tblLoans[[#This Row],[Status]]="REVIEWED",AND(NOT(OR(LOWER(TRIM(tblLoans[[#This Row],[Year_tested_text]]&""))={"","-","?","n/a","na","unk","unknown"})),NOT(IFERROR(AND(LEN(tblLoans[[#This Row],[Year_tested_text]])=7,MID(tblLoans[[#This Row],[Year_tested_text]],5,1)="-",ISNUMBER(VALUE(MID(tblLoans[[#This Row],[Year_tested_text]],1,1))),ISNUMBER(VALUE(MID(tblLoans[[#This Row],[Year_tested_text]],2,1))),ISNUMBER(VALUE(MID(tblLoans[[#This Row],[Year_tested_text]],3,1))),ISNUMBER(VALUE(MID(tblLoans[[#This Row],[Year_tested_text]],4,1))),ISNUMBER(VALUE(MID(tblLoans[[#This Row],[Year_tested_text]],6,1))),ISNUMBER(VALUE(MID(tblLoans[[#This Row],[Year_tested_text]],7,1))),VALUE(RIGHT(tblLoans[[#This Row],[Year_tested_text]],2))=MOD(VALUE(LEFT(tblLoans[[#This Row],[Year_tested_text]],4))+1,100),VALUE(LEFT(tblLoans[[#This Row],[Year_tested_text]],4))>=1900,VALUE(LEFT(tblLoans[[#This Row],[Year_tested_text]],4))<=2100),FALSE))))),"year label ","")&IF(tblLoans[[#This Row],[Status]]<>"REVIEWED","",IF(OR(AND(NOT(OR(LOWER(TRIM(tblLoans[[#This Row],[written_agreement]]&""))={"","-","?","n/a","na","unk","unknown"})),NOT(OR(LOWER(TRIM(tblLoans[[#This Row],[written_agreement]]&""))={"0","1","f","false","n","no","t","true","y","yes"}))),AND(NOT(OR(LOWER(TRIM(tblLoans[[#This Row],[terms_in_place_before_lodgment_day]]&""))={"","-","?","n/a","na","unk","unknown"})),NOT(OR(LOWER(TRIM(tblLoans[[#This Row],[terms_in_place_before_lodgment_day]]&""))={"0","1","f","false","n","no","t","true","y","yes"}))),AND(NOT(OR(LOWER(TRIM(tblLoans[[#This Row],[secured_by_registered_mortgage_over_real_property]]&""))={"","-","?","n/a","na","unk","unknown"})),NOT(OR(LOWER(TRIM(tblLoans[[#This Row],[secured_by_registered_mortgage_over_real_property]]&""))={"0","1","f","false","n","no","t","true","y","yes"})))),"true/false/unknown ","")&IF(OR(AND(NOT(OR(LOWER(TRIM(tblLoans[[#This Row],[maximum_term_years]]&""))={"","-","?","n/a","na","unk","unknown"})),OR(NOT(ISNUMBER(tblLoans[[#This Row],[maximum_term_years]])),AND(ISNUMBER(tblLoans[[#This Row],[maximum_term_years]]),OR(tblLoans[[#This Row],[maximum_term_years]]<0)))),AND(NOT(OR(LOWER(TRIM(tblLoans[[#This Row],[security_coverage_at_first_made]]&""))={"","-","?","n/a","na","unk","unknown"})),OR(NOT(ISNUMBER(tblLoans[[#This Row],[security_coverage_at_first_made]])),AND(ISNUMBER(tblLoans[[#This Row],[security_coverage_at_first_made]]),OR(tblLoans[[#This Row],[security_coverage_at_first_made]]<0)))),AND(NOT(OR(LOWER(TRIM(tblLoans[[#This Row],[interest_rate_for_years_after_year_loan_made]]&""))={"","-","?","n/a","na","unk","unknown"})),OR(NOT(ISNUMBER(tblLoans[[#This Row],[interest_rate_for_years_after_year_loan_made]])),AND(ISNUMBER(tblLoans[[#This Row],[interest_rate_for_years_after_year_loan_made]]),OR(tblLoans[[#This Row],[interest_rate_for_years_after_year_loan_made]]<0,tblLoans[[#This Row],[interest_rate_for_years_after_year_loan_made]]>1)))),AND(NOT(OR(LOWER(TRIM(tblLoans[[#This Row],[amalgamated_loan_unpaid_at_end_of_previous_year]]&""))={"","-","?","n/a","na","unk","unknown"})),OR(NOT(ISNUMBER(tblLoans[[#This Row],[amalgamated_loan_unpaid_at_end_of_previous_year]])),AND(ISNUMBER(tblLoans[[#This Row],[amalgamated_loan_unpaid_at_end_of_previous_year]]),OR(tblLoans[[#This Row],[amalgamated_loan_unpaid_at_end_of_previous_year]]<0,ROUND(N(tblLoans[[#This Row],[amalgamated_loan_unpaid_at_end_of_previous_year]]),2)<>N(tblLoans[[#This Row],[amalgamated_loan_unpaid_at_end_of_previous_year]]),N(tblLoans[[#This Row],[amalgamated_loan_unpaid_at_end_of_previous_year]])>1000000000000)))),AND(NOT(OR(LOWER(TRIM(tblLoans[[#This Row],[remaining_term_years]]&""))={"","-","?","n/a","na","unk","unknown"})),OR(NOT(ISNUMBER(tblLoans[[#This Row],[remaining_term_years]])),AND(ISNUMBER(tblLoans[[#This Row],[remaining_term_years]]),OR(tblLoans[[#This Row],[remaining_term_years]]<0)))),AND(NOT(OR(LOWER(TRIM(tblLoans[[#This Row],[payments_applied_during_the_year]]&""))={"","-","?","n/a","na","unk","unknown"})),OR(NOT(ISNUMBER(tblLoans[[#This Row],[payments_applied_during_the_year]])),AND(ISNUMBER(tblLoans[[#This Row],[payments_applied_during_the_year]]),OR(tblLoans[[#This Row],[payments_applied_during_the_year]]<0,ROUND(N(tblLoans[[#This Row],[payments_applied_during_the_year]]),2)<>N(tblLoans[[#This Row],[payments_applied_during_the_year]]),N(tblLoans[[#This Row],[payments_applied_during_the_year]])>1000000000000))))),"number ","")))) | AJ4: =IF(SUMPRODUCT((tblLoans[[#This Row],[loan_id]]&""={"L-101","L-102","L-103","L-104","L-105","L-106","L-107","L-108"})*(tblLoans[[#This Row],[Year_made_text]]&""={"2023-24","2022-23","2021-22","2024-25","2019-20","2020-21","2023-24","1996-97"}))>0,1,0) -> 1 | AK4: =TRIM(SUBSTITUTE(SUBSTITUTE(SUBSTITUTE(SUBSTITUTE(SUBSTITUTE(SUBSTITUTE(SUBSTITUTE(SUBSTITUTE(SUBSTITUTE(SUBSTITUTE(SUBSTITUTE(SUBSTITUTE(SUBSTITUTE(SUBSTITUTE(SUBSTITUTE(SUBSTITUTE(SUBSTITUTE(SUBSTITUTE(SUBSTITUTE(SUBSTITUTE(SUBSTITUTE(SUBSTITUTE(SUBSTITUTE(SUBSTITUTE(SUBSTITUTE(SUBSTITUTE(SUBSTITUTE(SUBSTITUTE(tblLoans[[#This Row],[year_loan_made]]&"",_xlfn.UNICHAR(9)," "),_xlfn.UNICHAR(10)," "),_xlfn.UNICHAR(11)," "),_xlfn.UNICHAR(12)," "),_xlfn.UNICHAR(13)," "),_xlfn.UNICHAR(28)," "),_xlfn.UNICHAR(29)," "),_xlfn.UNICHAR(30)," "),_xlfn.UNICHAR(31)," "),_xlfn.UNICHAR(133)," "),_xlfn.UNICHAR(160)," "),_xlfn.UNICHAR(5760)," "),_xlfn.UNICHAR(8192)," "),_xlfn.UNICHAR(8193)," "),_xlfn.UNICHAR(8194)," "),_xlfn.UNICHAR(8195)," "),_xlfn.UNICHAR(8196)," "),_xlfn.UNICHAR(8197)," "),_xlfn.UNICHAR(8198)," "),_xlfn.UNICHAR(8199)," "),_xlfn.UNICHAR(8200)," "),_xlfn.UNICHAR(8201)," "),_xlfn.UNICHAR(8202)," "),_xlfn.UNICHAR(8232)," "),_xlfn.UNICHAR(8233)," "),_xlfn.UNICHAR(8239)," "),_xlfn.UNICHAR(8287)," "),_xlfn.UNICHAR(12288)," ")) -> 2021-22 | AL4: =TRIM(SUBSTITUTE(SUBSTITUTE(SUBSTITUTE(SUBSTITUTE(SUBSTITUTE(SUBSTITUTE(SUBSTITUTE(SUBSTITUTE(SUBSTITUTE(SUBSTITUTE(SUBSTITUTE(SUBSTITUTE(SUBSTITUTE(SUBSTITUTE(SUBSTITUTE(SUBSTITUTE(SUBSTITUTE(SUBSTITUTE(SUBSTITUTE(SUBSTITUTE(SUBSTITUTE(SUBSTITUTE(SUBSTITUTE(SUBSTITUTE(SUBSTITUTE(SUBSTITUTE(SUBSTITUTE(SUBSTITUTE(tblLoans[[#This Row],[year_of_income_being_tested]]&"",_xlfn.UNICHAR(9)," "),_xlfn.UNICHAR(10)," "),_xlfn.UNICHAR(11)," "),_xlfn.UNICHAR(12)," "),_xlfn.UNICHAR(13)," "),_xlfn.UNICHAR(28)," "),_xlfn.UNICHAR(29)," "),_xlfn.UNICHAR(30)," "),_xlfn.UNICHAR(31)," "),_xlfn.UNICHAR(133)," "),_xlfn.UNICHAR(160)," "),_xlfn.UNICHAR(5760)," "),_xlfn.UNICHAR(8192)," "),_xlfn.UNICHAR(8193)," "),_xlfn.UNICHAR(8194)," "),_xlfn.UNICHAR(8195)," "),_xlfn.UNICHAR(8196)," "),_xlfn.UNICHAR(8197)," "),_xlfn.UNICHAR(8198)," "),_xlfn.UNICHAR(8199)," "),_xlfn.UNICHAR(8200)," "),_xlfn.UNICHAR(8201)," "),_xlfn.UNICHAR(8202)," "),_xlfn.UNICHAR(8232)," "),_xlfn.UNICHAR(8233)," "),_xlfn.UNICHAR(8239)," "),_xlfn.UNICHAR(8287)," "),_xlfn.UNICHAR(12288)," "))
