Workbook

Sheet Start Here
A1: ATO small business benchmark comparison
A3: 1. On P&L Import, paste account names and amounts over the example rows. Account cells are Text; nothing pasted there is evaluated.
A4: 2. On Mapping, give every account a bucket and set Source to reviewed. A suggested or missing mapping blocks the result.
A5: 3. On Calculation, choose the benchmark year and industry. Enter W1 if the activity statement labour figure is higher than wages. Set B4 to Y if the export shows expenses as negatives.
A6: 4. Read Results and Review Checks. The overall status below is BLOCKED, REVIEW or PASS; blank or an error is never a pass.
A7: 5. Sitting outside a published range is not a finding. The ATO ranges are review prompts, and the judgement stays with you. Nothing leaves this workbook.
A8: 6. Benchmarks and Sources & Version hold the published ranges, their provenance and the engine version this workbook was checked against.
A10: Overall status
A11: ='Review Checks'!B13 -> REVIEW
A13: ato-benchmark-compare workbook, engine 0.2.0. Macro-free. Not advice; see DISCLAIMER.md in the repository.

Sheet P&L Import
A1: Account | B1: Amount | C1: Bucket | D1: Guard | E1: Sample | F1: Key
A2: Sales - bread and rolls | B2: 520000 | C2: =IFERROR(INDEX(tblMapping[Bucket],MATCH(TRUE,INDEX(tblMapping[Key]=tblPnl[[#This Row],[Key]],0),0)),"") -> turnover | D2: =IF(OR(_xlfn.ISFORMULA(tblPnl[[#This Row],[Account]]),_xlfn.ISFORMULA(tblPnl[[#This Row],[Amount]]),AND(tblPnl[[#This Row],[Account]]<>"",NOT(ISNUMBER(tblPnl[[#This Row],[Amount]])))),1,0) -> 0 | E2: =IF(SUMPRODUCT((LOWER(TRIM(tblPnl[[#This Row],[Account]]))={"sales - bread and rolls","sales - cakes and pastries","interest received","total income","flour and ingredients","packaging","freight inwards","bakery wages","total cost of sales","gross profit","accounting fees","advertising","bank fees","cleaning contractor","depreciation","electricity","insurance","motor vehicle expenses","rent","repairs and maintenance","shop wages","superannuation","wages - director spouse","total operating expenses","net profit before tax","income tax expense","net profit"})*(tblPnl[[#This Row],[Amount]]={520000,330000,1200,851200,240000,24000,6000,95000,365000,486200,4800,3600,1900,7800,21000,18000,7400,9500,62000,6200,175000,24750,45000,386950,99250,12000,87250}))>0,1,0) -> 1 | F2: =TRIM(LOWER(tblPnl[[#This Row],[Account]])) -> sales - bread and rolls
A3: Sales - cakes and pastries | B3: 330000 | C3: =IFERROR(INDEX(tblMapping[Bucket],MATCH(TRUE,INDEX(tblMapping[Key]=tblPnl[[#This Row],[Key]],0),0)),"") -> turnover | D3: =IF(OR(_xlfn.ISFORMULA(tblPnl[[#This Row],[Account]]),_xlfn.ISFORMULA(tblPnl[[#This Row],[Amount]]),AND(tblPnl[[#This Row],[Account]]<>"",NOT(ISNUMBER(tblPnl[[#This Row],[Amount]])))),1,0) -> 0 | E3: =IF(SUMPRODUCT((LOWER(TRIM(tblPnl[[#This Row],[Account]]))={"sales - bread and rolls","sales - cakes and pastries","interest received","total income","flour and ingredients","packaging","freight inwards","bakery wages","total cost of sales","gross profit","accounting fees","advertising","bank fees","cleaning contractor","depreciation","electricity","insurance","motor vehicle expenses","rent","repairs and maintenance","shop wages","superannuation","wages - director spouse","total operating expenses","net profit before tax","income tax expense","net profit"})*(tblPnl[[#This Row],[Amount]]={520000,330000,1200,851200,240000,24000,6000,95000,365000,486200,4800,3600,1900,7800,21000,18000,7400,9500,62000,6200,175000,24750,45000,386950,99250,12000,87250}))>0,1,0) -> 1 | F3: =TRIM(LOWER(tblPnl[[#This Row],[Account]])) -> sales - cakes and pastries
A4: Interest received | B4: 1200 | C4: =IFERROR(INDEX(tblMapping[Bucket],MATCH(TRUE,INDEX(tblMapping[Key]=tblPnl[[#This Row],[Key]],0),0)),"") -> other_income | D4: =IF(OR(_xlfn.ISFORMULA(tblPnl[[#This Row],[Account]]),_xlfn.ISFORMULA(tblPnl[[#This Row],[Amount]]),AND(tblPnl[[#This Row],[Account]]<>"",NOT(ISNUMBER(tblPnl[[#This Row],[Amount]])))),1,0) -> 0 | E4: =IF(SUMPRODUCT((LOWER(TRIM(tblPnl[[#This Row],[Account]]))={"sales - bread and rolls","sales - cakes and pastries","interest received","total income","flour and ingredients","packaging","freight inwards","bakery wages","total cost of sales","gross profit","accounting fees","advertising","bank fees","cleaning contractor","depreciation","electricity","insurance","motor vehicle expenses","rent","repairs and maintenance","shop wages","superannuation","wages - director spouse","total operating expenses","net profit before tax","income tax expense","net profit"})*(tblPnl[[#This Row],[Amount]]={520000,330000,1200,851200,240000,24000,6000,95000,365000,486200,4800,3600,1900,7800,21000,18000,7400,9500,62000,6200,175000,24750,45000,386950,99250,12000,87250}))>0,1,0) -> 1 | F4: =TRIM(LOWER(tblPnl[[#This Row],[Account]])) -> interest received
A5: Total Income | B5: 851200 | C5: =IFERROR(INDEX(tblMapping[Bucket],MATCH(TRUE,INDEX(tblMapping[Key]=tblPnl[[#This Row],[Key]],0),0)),"") -> excluded | D5: =IF(OR(_xlfn.ISFORMULA(tblPnl[[#This Row],[Account]]),_xlfn.ISFORMULA(tblPnl[[#This Row],[Amount]]),AND(tblPnl[[#This Row],[Account]]<>"",NOT(ISNUMBER(tblPnl[[#This Row],[Amount]])))),1,0) -> 0 | E5: =IF(SUMPRODUCT((LOWER(TRIM(tblPnl[[#This Row],[Account]]))={"sales - bread and rolls","sales - cakes and pastries","interest received","total income","flour and ingredients","packaging","freight inwards","bakery wages","total cost of sales","gross profit","accounting fees","advertising","bank fees","cleaning contractor","depreciation","electricity","insurance","motor vehicle expenses","rent","repairs and maintenance","shop wages","superannuation","wages - director spouse","total operating expenses","net profit before tax","income tax expense","net profit"})*(tblPnl[[#This Row],[Amount]]={520000,330000,1200,851200,240000,24000,6000,95000,365000,486200,4800,3600,1900,7800,21000,18000,7400,9500,62000,6200,175000,24750,45000,386950,99250,12000,87250}))>0,1,0) -> 1 | F5: =TRIM(LOWER(tblPnl[[#This Row],[Account]])) -> total income
A6: Flour and ingredients | B6: 240000 | C6: =IFERROR(INDEX(tblMapping[Bucket],MATCH(TRUE,INDEX(tblMapping[Key]=tblPnl[[#This Row],[Key]],0),0)),"") -> cost_of_sales | D6: =IF(OR(_xlfn.ISFORMULA(tblPnl[[#This Row],[Account]]),_xlfn.ISFORMULA(tblPnl[[#This Row],[Amount]]),AND(tblPnl[[#This Row],[Account]]<>"",NOT(ISNUMBER(tblPnl[[#This Row],[Amount]])))),1,0) -> 0 | E6: =IF(SUMPRODUCT((LOWER(TRIM(tblPnl[[#This Row],[Account]]))={"sales - bread and rolls","sales - cakes and pastries","interest received","total income","flour and ingredients","packaging","freight inwards","bakery wages","total cost of sales","gross profit","accounting fees","advertising","bank fees","cleaning contractor","depreciation","electricity","insurance","motor vehicle expenses","rent","repairs and maintenance","shop wages","superannuation","wages - director spouse","total operating expenses","net profit before tax","income tax expense","net profit"})*(tblPnl[[#This Row],[Amount]]={520000,330000,1200,851200,240000,24000,6000,95000,365000,486200,4800,3600,1900,7800,21000,18000,7400,9500,62000,6200,175000,24750,45000,386950,99250,12000,87250}))>0,1,0) -> 1 | F6: =TRIM(LOWER(tblPnl[[#This Row],[Account]])) -> flour and ingredients
A7: Packaging | B7: 24000 | C7: =IFERROR(INDEX(tblMapping[Bucket],MATCH(TRUE,INDEX(tblMapping[Key]=tblPnl[[#This Row],[Key]],0),0)),"") -> cost_of_sales | D7: =IF(OR(_xlfn.ISFORMULA(tblPnl[[#This Row],[Account]]),_xlfn.ISFORMULA(tblPnl[[#This Row],[Amount]]),AND(tblPnl[[#This Row],[Account]]<>"",NOT(ISNUMBER(tblPnl[[#This Row],[Amount]])))),1,0) -> 0 | E7: =IF(SUMPRODUCT((LOWER(TRIM(tblPnl[[#This Row],[Account]]))={"sales - bread and rolls","sales - cakes and pastries","interest received","total income","flour and ingredients","packaging","freight inwards","bakery wages","total cost of sales","gross profit","accounting fees","advertising","bank fees","cleaning contractor","depreciation","electricity","insurance","motor vehicle expenses","rent","repairs and maintenance","shop wages","superannuation","wages - director spouse","total operating expenses","net profit before tax","income tax expense","net profit"})*(tblPnl[[#This Row],[Amount]]={520000,330000,1200,851200,240000,24000,6000,95000,365000,486200,4800,3600,1900,7800,21000,18000,7400,9500,62000,6200,175000,24750,45000,386950,99250,12000,87250}))>0,1,0) -> 1 | F7: =TRIM(LOWER(tblPnl[[#This Row],[Account]])) -> packaging
A8: Freight inwards | B8: 6000 | C8: =IFERROR(INDEX(tblMapping[Bucket],MATCH(TRUE,INDEX(tblMapping[Key]=tblPnl[[#This Row],[Key]],0),0)),"") -> cost_of_sales | D8: =IF(OR(_xlfn.ISFORMULA(tblPnl[[#This Row],[Account]]),_xlfn.ISFORMULA(tblPnl[[#This Row],[Amount]]),AND(tblPnl[[#This Row],[Account]]<>"",NOT(ISNUMBER(tblPnl[[#This Row],[Amount]])))),1,0) -> 0 | E8: =IF(SUMPRODUCT((LOWER(TRIM(tblPnl[[#This Row],[Account]]))={"sales - bread and rolls","sales - cakes and pastries","interest received","total income","flour and ingredients","packaging","freight inwards","bakery wages","total cost of sales","gross profit","accounting fees","advertising","bank fees","cleaning contractor","depreciation","electricity","insurance","motor vehicle expenses","rent","repairs and maintenance","shop wages","superannuation","wages - director spouse","total operating expenses","net profit before tax","income tax expense","net profit"})*(tblPnl[[#This Row],[Amount]]={520000,330000,1200,851200,240000,24000,6000,95000,365000,486200,4800,3600,1900,7800,21000,18000,7400,9500,62000,6200,175000,24750,45000,386950,99250,12000,87250}))>0,1,0) -> 1 | F8: =TRIM(LOWER(tblPnl[[#This Row],[Account]])) -> freight inwards
A9: Bakery wages | B9: 95000 | C9: =IFERROR(INDEX(tblMapping[Bucket],MATCH(TRUE,INDEX(tblMapping[Key]=tblPnl[[#This Row],[Key]],0),0)),"") -> cost_of_sales_labour | D9: =IF(OR(_xlfn.ISFORMULA(tblPnl[[#This Row],[Account]]),_xlfn.ISFORMULA(tblPnl[[#This Row],[Amount]]),AND(tblPnl[[#This Row],[Account]]<>"",NOT(ISNUMBER(tblPnl[[#This Row],[Amount]])))),1,0) -> 0 | E9: =IF(SUMPRODUCT((LOWER(TRIM(tblPnl[[#This Row],[Account]]))={"sales - bread and rolls","sales - cakes and pastries","interest received","total income","flour and ingredients","packaging","freight inwards","bakery wages","total cost of sales","gross profit","accounting fees","advertising","bank fees","cleaning contractor","depreciation","electricity","insurance","motor vehicle expenses","rent","repairs and maintenance","shop wages","superannuation","wages - director spouse","total operating expenses","net profit before tax","income tax expense","net profit"})*(tblPnl[[#This Row],[Amount]]={520000,330000,1200,851200,240000,24000,6000,95000,365000,486200,4800,3600,1900,7800,21000,18000,7400,9500,62000,6200,175000,24750,45000,386950,99250,12000,87250}))>0,1,0) -> 1 | F9: =TRIM(LOWER(tblPnl[[#This Row],[Account]])) -> bakery wages
A10: Total Cost of Sales | B10: 365000 | C10: =IFERROR(INDEX(tblMapping[Bucket],MATCH(TRUE,INDEX(tblMapping[Key]=tblPnl[[#This Row],[Key]],0),0)),"") -> excluded | D10: =IF(OR(_xlfn.ISFORMULA(tblPnl[[#This Row],[Account]]),_xlfn.ISFORMULA(tblPnl[[#This Row],[Amount]]),AND(tblPnl[[#This Row],[Account]]<>"",NOT(ISNUMBER(tblPnl[[#This Row],[Amount]])))),1,0) -> 0 | E10: =IF(SUMPRODUCT((LOWER(TRIM(tblPnl[[#This Row],[Account]]))={"sales - bread and rolls","sales - cakes and pastries","interest received","total income","flour and ingredients","packaging","freight inwards","bakery wages","total cost of sales","gross profit","accounting fees","advertising","bank fees","cleaning contractor","depreciation","electricity","insurance","motor vehicle expenses","rent","repairs and maintenance","shop wages","superannuation","wages - director spouse","total operating expenses","net profit before tax","income tax expense","net profit"})*(tblPnl[[#This Row],[Amount]]={520000,330000,1200,851200,240000,24000,6000,95000,365000,486200,4800,3600,1900,7800,21000,18000,7400,9500,62000,6200,175000,24750,45000,386950,99250,12000,87250}))>0,1,0) -> 1 | F10: =TRIM(LOWER(tblPnl[[#This Row],[Account]])) -> total cost of sales
A11: Gross Profit | B11: 486200 | C11: =IFERROR(INDEX(tblMapping[Bucket],MATCH(TRUE,INDEX(tblMapping[Key]=tblPnl[[#This Row],[Key]],0),0)),"") -> excluded | D11: =IF(OR(_xlfn.ISFORMULA(tblPnl[[#This Row],[Account]]),_xlfn.ISFORMULA(tblPnl[[#This Row],[Amount]]),AND(tblPnl[[#This Row],[Account]]<>"",NOT(ISNUMBER(tblPnl[[#This Row],[Amount]])))),1,0) -> 0 | E11: =IF(SUMPRODUCT((LOWER(TRIM(tblPnl[[#This Row],[Account]]))={"sales - bread and rolls","sales - cakes and pastries","interest received","total income","flour and ingredients","packaging","freight inwards","bakery wages","total cost of sales","gross profit","accounting fees","advertising","bank fees","cleaning contractor","depreciation","electricity","insurance","motor vehicle expenses","rent","repairs and maintenance","shop wages","superannuation","wages - director spouse","total operating expenses","net profit before tax","income tax expense","net profit"})*(tblPnl[[#This Row],[Amount]]={520000,330000,1200,851200,240000,24000,6000,95000,365000,486200,4800,3600,1900,7800,21000,18000,7400,9500,62000,6200,175000,24750,45000,386950,99250,12000,87250}))>0,1,0) -> 1 | F11: =TRIM(LOWER(tblPnl[[#This Row],[Account]])) -> gross profit
A12: Accounting fees | B12: 4800 | C12: =IFERROR(INDEX(tblMapping[Bucket],MATCH(TRUE,INDEX(tblMapping[Key]=tblPnl[[#This Row],[Key]],0),0)),"") -> other_expense | D12: =IF(OR(_xlfn.ISFORMULA(tblPnl[[#This Row],[Account]]),_xlfn.ISFORMULA(tblPnl[[#This Row],[Amount]]),AND(tblPnl[[#This Row],[Account]]<>"",NOT(ISNUMBER(tblPnl[[#This Row],[Amount]])))),1,0) -> 0 | E12: =IF(SUMPRODUCT((LOWER(TRIM(tblPnl[[#This Row],[Account]]))={"sales - bread and rolls","sales - cakes and pastries","interest received","total income","flour and ingredients","packaging","freight inwards","bakery wages","total cost of sales","gross profit","accounting fees","advertising","bank fees","cleaning contractor","depreciation","electricity","insurance","motor vehicle expenses","rent","repairs and maintenance","shop wages","superannuation","wages - director spouse","total operating expenses","net profit before tax","income tax expense","net profit"})*(tblPnl[[#This Row],[Amount]]={520000,330000,1200,851200,240000,24000,6000,95000,365000,486200,4800,3600,1900,7800,21000,18000,7400,9500,62000,6200,175000,24750,45000,386950,99250,12000,87250}))>0,1,0) -> 1 | F12: =TRIM(LOWER(tblPnl[[#This Row],[Account]])) -> accounting fees
A13: Advertising | B13: 3600 | C13: =IFERROR(INDEX(tblMapping[Bucket],MATCH(TRUE,INDEX(tblMapping[Key]=tblPnl[[#This Row],[Key]],0),0)),"") -> other_expense | D13: =IF(OR(_xlfn.ISFORMULA(tblPnl[[#This Row],[Account]]),_xlfn.ISFORMULA(tblPnl[[#This Row],[Amount]]),AND(tblPnl[[#This Row],[Account]]<>"",NOT(ISNUMBER(tblPnl[[#This Row],[Amount]])))),1,0) -> 0 | E13: =IF(SUMPRODUCT((LOWER(TRIM(tblPnl[[#This Row],[Account]]))={"sales - bread and rolls","sales - cakes and pastries","interest received","total income","flour and ingredients","packaging","freight inwards","bakery wages","total cost of sales","gross profit","accounting fees","advertising","bank fees","cleaning contractor","depreciation","electricity","insurance","motor vehicle expenses","rent","repairs and maintenance","shop wages","superannuation","wages - director spouse","total operating expenses","net profit before tax","income tax expense","net profit"})*(tblPnl[[#This Row],[Amount]]={520000,330000,1200,851200,240000,24000,6000,95000,365000,486200,4800,3600,1900,7800,21000,18000,7400,9500,62000,6200,175000,24750,45000,386950,99250,12000,87250}))>0,1,0) -> 1 | F13: =TRIM(LOWER(tblPnl[[#This Row],[Account]])) -> advertising
... A28: Net Profit | B28: 87250 | C28: =IFERROR(INDEX(tblMapping[Bucket],MATCH(TRUE,INDEX(tblMapping[Key]=tblPnl[[#This Row],[Key]],0),0)),"") -> excluded | D28: =IF(OR(_xlfn.ISFORMULA(tblPnl[[#This Row],[Account]]),_xlfn.ISFORMULA(tblPnl[[#This Row],[Amount]]),AND(tblPnl[[#This Row],[Account]]<>"",NOT(ISNUMBER(tblPnl[[#This Row],[Amount]])))),1,0) -> 0 | E28: =IF(SUMPRODUCT((LOWER(TRIM(tblPnl[[#This Row],[Account]]))={"sales - bread and rolls","sales - cakes and pastries","interest received","total income","flour and ingredients","packaging","freight inwards","bakery wages","total cost of sales","gross profit","accounting fees","advertising","bank fees","cleaning contractor","depreciation","electricity","insurance","motor vehicle expenses","rent","repairs and maintenance","shop wages","superannuation","wages - director spouse","total operating expenses","net profit before tax","income tax expense","net profit"})*(tblPnl[[#This Row],[Amount]]={520000,330000,1200,851200,240000,24000,6000,95000,365000,486200,4800,3600,1900,7800,21000,18000,7400,9500,62000,6200,175000,24750,45000,386950,99250,12000,87250}))>0,1,0) -> 1 | F28: =TRIM(LOWER(tblPnl[[#This Row],[Account]])) -> net profit

Sheet Mapping
A1: Account | B1: Bucket | C1: Source | D1: Note | E1: Key
A2: Sales - bread and rolls | B2: turnover | C2: reviewed | D2: sales wording | E2: =TRIM(LOWER(tblMapping[[#This Row],[Account]])) -> sales - bread and rolls
A3: Sales - cakes and pastries | B3: turnover | C3: reviewed | D3: sales wording | E3: =TRIM(LOWER(tblMapping[[#This Row],[Account]])) -> sales - cakes and pastries
A4: Interest received | B4: other_income | C4: reviewed | D4: not sales of goods or services | E4: =TRIM(LOWER(tblMapping[[#This Row],[Account]])) -> interest received
A5: Total Income | B5: excluded | C5: reviewed | D5: looks like a subtotal row, so it is left out | E5: =TRIM(LOWER(tblMapping[[#This Row],[Account]])) -> total income
A6: Flour and ingredients | B6: cost_of_sales | C6: reviewed | D6: in the cost of sales section, no more specific rule matched | E6: =TRIM(LOWER(tblMapping[[#This Row],[Account]])) -> flour and ingredients
A7: Packaging | B7: cost_of_sales | C7: reviewed | D7: in the cost of sales section, no more specific rule matched | E7: =TRIM(LOWER(tblMapping[[#This Row],[Account]])) -> packaging
A8: Freight inwards | B8: cost_of_sales | C8: reviewed | D8: in the cost of sales section, no more specific rule matched | E8: =TRIM(LOWER(tblMapping[[#This Row],[Account]])) -> freight inwards
A9: Bakery wages | B9: cost_of_sales_labour | C9: reviewed | D9: wages inside the cost of sales section | E9: =TRIM(LOWER(tblMapping[[#This Row],[Account]])) -> bakery wages
A10: Total Cost of Sales | B10: excluded | C10: reviewed | D10: looks like a subtotal row, so it is left out | E10: =TRIM(LOWER(tblMapping[[#This Row],[Account]])) -> total cost of sales
A11: Gross Profit | B11: excluded | C11: reviewed | D11: looks like a subtotal row, so it is left out | E11: =TRIM(LOWER(tblMapping[[#This Row],[Account]])) -> gross profit
A12: Accounting fees | B12: other_expense | C12: reviewed | D12: in the expense section, no more specific rule matched | E12: =TRIM(LOWER(tblMapping[[#This Row],[Account]])) -> accounting fees
A13: Advertising | B13: other_expense | C13: reviewed | D13: in the expense section, no more specific rule matched | E13: =TRIM(LOWER(tblMapping[[#This Row],[Account]])) -> advertising
... A28: Net Profit | B28: excluded | C28: reviewed | D28: looks like a subtotal row, so it is left out | E28: =TRIM(LOWER(tblMapping[[#This Row],[Account]])) -> net profit

Sheet Benchmarks
A1: Year | B1: Industry | C1: KeyRatio | D1: Band | E1: Label | F1: From | G1: FromInclusive | H1: To | I1: CostOfSalesMin | J1: CostOfSalesMax | K1: TotalExpensesMin | L1: TotalExpensesMax | M1: Retrieved | N1: Sha256 | O1: LabourMin | P1: LabourMax | Q1: RentMin | R1: RentMax | S1: MotorVehicleMin | T1: MotorVehicleMax | U1: PageRanges | V1: PageSha256 | X1: Industries
A2: 2022-23 | B2: Air conditioning, refrigeration and heating services | C2: total_expenses_to_turnover | D2: low | E2: $50,000 - $150,000 | F2: 50000 | G2: Y | H2: 150000 | K2: 0.54 | L2: 0.73 | M2: 2026-08-13 | N2: ecd9ad5169fcdc4ddd5fdf79ceabeee460e950328fa87c8eaa224260e07548c6 | X2: Air conditioning, refrigeration and heating services
A3: 2022-23 | B3: Air conditioning, refrigeration and heating services | C3: total_expenses_to_turnover | D3: medium | E3: $150,001 - $600,000 | F3: 150000 | G3: N | H3: 600000 | K3: 0.66 | L3: 0.8 | M3: 2026-08-13 | N3: ecd9ad5169fcdc4ddd5fdf79ceabeee460e950328fa87c8eaa224260e07548c6 | X3: Alarm systems installation - fire and security
A4: 2022-23 | B4: Air conditioning, refrigeration and heating services | C4: total_expenses_to_turnover | D4: high | E4: More than $600,000 | F4: 600000 | G4: N | K4: 0.81 | L4: 0.9 | M4: 2026-08-13 | N4: ecd9ad5169fcdc4ddd5fdf79ceabeee460e950328fa87c8eaa224260e07548c6 | X4: Architectural services
A5: 2022-23 | B5: Alarm systems installation - fire and security | C5: total_expenses_to_turnover | D5: low | E5: $50,000 - $150,000 | F5: 50000 | G5: Y | H5: 150000 | K5: 0.53 | L5: 0.7 | M5: 2026-08-13 | N5: ecd9ad5169fcdc4ddd5fdf79ceabeee460e950328fa87c8eaa224260e07548c6 | X5: Automotive electrical services
A6: 2022-23 | B6: Alarm systems installation - fire and security | C6: total_expenses_to_turnover | D6: medium | E6: $150,001 - $600,000 | F6: 150000 | G6: N | H6: 600000 | K6: 0.62 | L6: 0.77 | M6: 2026-08-13 | N6: ecd9ad5169fcdc4ddd5fdf79ceabeee460e950328fa87c8eaa224260e07548c6 | X6: Bakeries and hot bread shops
A7: 2022-23 | B7: Alarm systems installation - fire and security | C7: total_expenses_to_turnover | D7: high | E7: More than $600,000 | F7: 600000 | G7: N | K7: 0.77 | L7: 0.88 | M7: 2026-08-13 | N7: ecd9ad5169fcdc4ddd5fdf79ceabeee460e950328fa87c8eaa224260e07548c6 | X7: Barber and men's hairdressing
A8: 2022-23 | B8: Architectural services | C8: total_expenses_to_turnover | D8: low | E8: $105,000 - $195,000 | F8: 105000 | G8: Y | H8: 195000 | K8: 0.29 | L8: 0.54 | M8: 2026-08-13 | N8: ecd9ad5169fcdc4ddd5fdf79ceabeee460e950328fa87c8eaa224260e07548c6 | X8: Beauty services
A9: 2022-23 | B9: Architectural services | C9: total_expenses_to_turnover | D9: medium | E9: $195,001 - $400,000 | F9: 195000 | G9: N | H9: 400000 | K9: 0.4 | L9: 0.65 | M9: 2026-08-13 | N9: ecd9ad5169fcdc4ddd5fdf79ceabeee460e950328fa87c8eaa224260e07548c6 | X9: Blocklaying services
A10: 2022-23 | B10: Architectural services | C10: total_expenses_to_turnover | D10: high | E10: More than $400,000 | F10: 400000 | G10: N | K10: 0.62 | L10: 0.79 | M10: 2026-08-13 | N10: ecd9ad5169fcdc4ddd5fdf79ceabeee460e950328fa87c8eaa224260e07548c6 | X10: Book retailing
A11: 2022-23 | B11: Automotive electrical services | C11: cost_of_sales_to_turnover | D11: low | E11: $50,000 - $250,000 | F11: 50000 | G11: Y | H11: 250000 | I11: 0.3 | J11: 0.42 | K11: 0.6 | L11: 0.74 | M11: 2026-08-13 | N11: ecd9ad5169fcdc4ddd5fdf79ceabeee460e950328fa87c8eaa224260e07548c6 | X11: Bottle shops and liquor retailing
A12: 2022-23 | B12: Automotive electrical services | C12: cost_of_sales_to_turnover | D12: medium | E12: $250,001 - $750,000 | F12: 250000 | G12: N | H12: 750000 | I12: 0.35 | J12: 0.44 | K12: 0.68 | L12: 0.82 | M12: 2026-08-13 | N12: ecd9ad5169fcdc4ddd5fdf79ceabeee460e950328fa87c8eaa224260e07548c6 | X12: Bricklaying services
A13: 2022-23 | B13: Automotive electrical services | C13: cost_of_sales_to_turnover | D13: high | E13: More than $750,000 | F13: 750000 | G13: N | I13: 0.38 | J13: 0.46 | K13: 0.79 | L13: 0.88 | M13: 2026-08-13 | N13: ecd9ad5169fcdc4ddd5fdf79ceabeee460e950328fa87c8eaa224260e07548c6 | X13: Cabinet makers
A14: 2022-23 | B14: Bakeries and hot bread shops | C14: cost_of_sales_to_turnover | D14: low | E14: $65,000 - $400,000 | F14: 65000 | G14: Y | H14: 400000 | I14: 0.3 | J14: 0.38 | K14: 0.7 | L14: 0.82 | M14: 2026-08-13 | N14: ecd9ad5169fcdc4ddd5fdf79ceabeee460e950328fa87c8eaa224260e07548c6 | X14: Cake shops and patisseries
A15: 2022-23 | B15: Bakeries and hot bread shops | C15: cost_of_sales_to_turnover | D15: medium | E15: $400,001 - $750,000 | F15: 400000 | G15: N | H15: 750000 | I15: 0.34 | J15: 0.39 | K15: 0.76 | L15: 0.86 | M15: 2026-08-13 | N15: ecd9ad5169fcdc4ddd5fdf79ceabeee460e950328fa87c8eaa224260e07548c6 | X15: Carpentry services
A16: 2022-23 | B16: Bakeries and hot bread shops | C16: cost_of_sales_to_turnover | D16: high | E16: More than $750,000 | F16: 750000 | G16: N | I16: 0.3 | J16: 0.36 | K16: 0.82 | L16: 0.9 | M16: 2026-08-13 | N16: ecd9ad5169fcdc4ddd5fdf79ceabeee460e950328fa87c8eaa224260e07548c6 | X16: Carpet laying services
A17: 2022-23 | B17: Barber and men's hairdressing | C17: total_expenses_to_turnover | D17: low | E17: $65,000 - $150,000 | F17: 65000 | G17: Y | H17: 150000 | K17: 0.43 | L17: 0.62 | M17: 2026-08-13 | N17: ecd9ad5169fcdc4ddd5fdf79ceabeee460e950328fa87c8eaa224260e07548c6 | X17: Catering services
A18: 2022-23 | B18: Barber and men's hairdressing | C18: total_expenses_to_turnover | D18: medium | E18: More than $150,000 | F18: 150000 | G18: N | K18: 0.67 | L18: 0.82 | M18: 2026-08-13 | N18: ecd9ad5169fcdc4ddd5fdf79ceabeee460e950328fa87c8eaa224260e07548c6 | X18: Cement rendering
A19: 2022-23 | B19: Beauty services | C19: total_expenses_to_turnover | D19: low | E19: $65,000 - $200,000 | F19: 65000 | G19: Y | H19: 200000 | K19: 0.49 | L19: 0.69 | M19: 2026-08-13 | N19: ecd9ad5169fcdc4ddd5fdf79ceabeee460e950328fa87c8eaa224260e07548c6 | X19: Chicken shops
A20: 2022-23 | B20: Beauty services | C20: total_expenses_to_turnover | D20: medium | E20: $200,001 - $400,000 | F20: 200000 | G20: N | H20: 400000 | K20: 0.7 | L20: 0.83 | M20: 2026-08-13 | N20: ecd9ad5169fcdc4ddd5fdf79ceabeee460e950328fa87c8eaa224260e07548c6 | X20: Child care services
A21: 2022-23 | B21: Beauty services | C21: total_expenses_to_turnover | D21: high | E21: More than $400,000 | F21: 400000 | G21: N | K21: 0.76 | L21: 0.88 | M21: 2026-08-13 | N21: ecd9ad5169fcdc4ddd5fdf79ceabeee460e950328fa87c8eaa224260e07548c6 | X21: Chiropractic and osteopathic services
A22: 2022-23 | B22: Blocklaying services | C22: total_expenses_to_turnover | D22: low | E22: $75,000 - $155,000 | F22: 75000 | G22: Y | H22: 155000 | K22: 0.4 | L22: 0.6 | M22: 2026-08-13 | N22: ecd9ad5169fcdc4ddd5fdf79ceabeee460e950328fa87c8eaa224260e07548c6 | X22: Cleaning services - building and other industrial
A23: 2022-23 | B23: Blocklaying services | C23: total_expenses_to_turnover | D23: medium | E23: $155,001 - $500,000 | F23: 155000 | G23: N | H23: 500000 | K23: 0.6 | L23: 0.74 | M23: 2026-08-13 | N23: ecd9ad5169fcdc4ddd5fdf79ceabeee460e950328fa87c8eaa224260e07548c6 | X23: Cleaning services - carpet, rug and furniture upholstery
A24: 2022-23 | B24: Blocklaying services | C24: total_expenses_to_turnover | D24: high | E24: More than $500,000 | F24: 500000 | G24: N | K24: 0.79 | L24: 0.88 | M24: 2026-08-13 | N24: ecd9ad5169fcdc4ddd5fdf79ceabeee460e950328fa87c8eaa224260e07548c6 | X24: Clothing retailing
A25: 2022-23 | B25: Book retailing | C25: cost_of_sales_to_turnover | D25: low | E25: $65,000 - $250,000 | F25: 65000 | G25: Y | H25: 250000 | I25: 0.29 | J25: 0.53 | K25: 0.69 | L25: 0.82 | M25: 2026-08-13 | N25: ecd9ad5169fcdc4ddd5fdf79ceabeee460e950328fa87c8eaa224260e07548c6 | X25: Coffee shops
A26: 2022-23 | B26: Book retailing | C26: cost_of_sales_to_turnover | D26: medium | E26: $250,001 - $750,000 | F26: 250000 | G26: N | H26: 750000 | I26: 0.47 | J26: 0.57 | K26: 0.79 | L26: 0.86 | M26: 2026-08-13 | N26: ecd9ad5169fcdc4ddd5fdf79ceabeee460e950328fa87c8eaa224260e07548c6 | X26: Computer retailing
A27: 2022-23 | B27: Book retailing | C27: cost_of_sales_to_turnover | D27: high | E27: More than $750,000 | F27: 750000 | G27: N | I27: 0.52 | J27: 0.56 | K27: 0.85 | L27: 0.93 | M27: 2026-08-13 | N27: ecd9ad5169fcdc4ddd5fdf79ceabeee460e950328fa87c8eaa224260e07548c6 | X27: Concreting services
A28: 2022-23 | B28: Bottle shops and liquor retailing | C28: cost_of_sales_to_turnover | D28: low | E28: $65,000 - $500,000 | F28: 65000 | G28: Y | H28: 500000 | I28: 0.62 | J28: 0.74 | K28: 0.78 | L28: 0.9 | M28: 2026-08-13 | N28: ecd9ad5169fcdc4ddd5fdf79ceabeee460e950328fa87c8eaa224260e07548c6 | X28: Confectionery retailing
A29: 2022-23 | B29: Bottle shops and liquor retailing | C29: cost_of_sales_to_turnover | D29: medium | E29: $500,001 - $2,000,000 | F29: 500000 | G29: N | H29: 2000000 | I29: 0.7 | J29: 0.77 | K29: 0.9 | L29: 0.95 | M29: 2026-08-13 | N29: ecd9ad5169fcdc4ddd5fdf79ceabeee460e950328fa87c8eaa224260e07548c6 | X29: Courier services
A30: 2022-23 | B30: Bottle shops and liquor retailing | C30: cost_of_sales_to_turnover | D30: high | E30: More than $2,000,000 | F30: 2000000 | G30: N | I30: 0.74 | J30: 0.78 | K30: 0.91 | L30: 0.95 | M30: 2026-08-13 | N30: ecd9ad5169fcdc4ddd5fdf79ceabeee460e950328fa87c8eaa224260e07548c6 | X30: Craft shops
A31: 2022-23 | B31: Bricklaying services | C31: total_expenses_to_turnover | D31: low | E31: $50,000 - $150,000 | F31: 50000 | G31: Y | H31: 150000 | K31: 0.3 | L31: 0.48 | M31: 2026-08-13 | N31: ecd9ad5169fcdc4ddd5fdf79ceabeee460e950328fa87c8eaa224260e07548c6 | X31: Delicatessen
A32: 2022-23 | B32: Bricklaying services | C32: total_expenses_to_turnover | D32: medium | E32: $150,001 - $350,000 | F32: 150000 | G32: N | H32: 350000 | K32: 0.52 | L32: 0.69 | M32: 2026-08-13 | N32: ecd9ad5169fcdc4ddd5fdf79ceabeee460e950328fa87c8eaa224260e07548c6 | X32: Delivery services
A33: 2022-23 | B33: Bricklaying services | C33: total_expenses_to_turnover | D33: high | E33: More than $350,000 | F33: 350000 | G33: N | K33: 0.69 | L33: 0.83 | M33: 2026-08-13 | N33: ecd9ad5169fcdc4ddd5fdf79ceabeee460e950328fa87c8eaa224260e07548c6 | X33: Dental specialists
A34: 2022-23 | B34: Cabinet makers | C34: total_expenses_to_turnover | D34: low | E34: $100,000 - $300,000 | F34: 100000 | G34: Y | H34: 300000 | K34: 0.55 | L34: 0.72 | M34: 2026-08-13 | N34: ecd9ad5169fcdc4ddd5fdf79ceabeee460e950328fa87c8eaa224260e07548c6 | X34: Dental surgeons - general
A35: 2022-23 | B35: Cabinet makers | C35: total_expenses_to_turnover | D35: medium | E35: $300,001 - $900,000 | F35: 300000 | G35: N | H35: 900000 | K35: 0.73 | L35: 0.84 | M35: 2026-08-13 | N35: ecd9ad5169fcdc4ddd5fdf79ceabeee460e950328fa87c8eaa224260e07548c6 | X35: Discount and variety stores
A36: 2022-23 | B36: Cabinet makers | C36: total_expenses_to_turnover | D36: high | E36: More than $900,000 | F36: 900000 | G36: N | K36: 0.83 | L36: 0.91 | M36: 2026-08-13 | N36: ecd9ad5169fcdc4ddd5fdf79ceabeee460e950328fa87c8eaa224260e07548c6 | X36: Domestic appliance repair and maintenance
A37: 2022-23 | B37: Cake shops and patisseries | C37: cost_of_sales_to_turnover | D37: low | E37: $65,000 - $300,000 | F37: 65000 | G37: Y | H37: 300000 | I37: 0.29 | J37: 0.36 | K37: 0.6 | L37: 0.76 | M37: 2026-08-13 | N37: ecd9ad5169fcdc4ddd5fdf79ceabeee460e950328fa87c8eaa224260e07548c6 | X37: Driving schools and instructors
A38: 2022-23 | B38: Cake shops and patisseries | C38: cost_of_sales_to_turnover | D38: medium | E38: $300,001 - $600,000 | F38: 300000 | G38: N | H38: 600000 | I38: 0.31 | J38: 0.38 | K38: 0.8 | L38: 0.89 | M38: 2026-08-13 | N38: ecd9ad5169fcdc4ddd5fdf79ceabeee460e950328fa87c8eaa224260e07548c6 | X38: Electrical and electronic product retailing
A39: 2022-23 | B39: Cake shops and patisseries | C39: cost_of_sales_to_turnover | D39: high | E39: More than $600,000 | F39: 600000 | G39: N | I39: 0.31 | J39: 0.36 | K39: 0.81 | L39: 0.9 | M39: 2026-08-13 | N39: ecd9ad5169fcdc4ddd5fdf79ceabeee460e950328fa87c8eaa224260e07548c6 | X39: Electrical services
A40: 2022-23 | B40: Carpentry services | C40: total_expenses_to_turnover | D40: low | E40: $50,000 - $110,000 | F40: 50000 | G40: Y | H40: 110000 | K40: 0.32 | L40: 0.52 | M40: 2026-08-13 | N40: ecd9ad5169fcdc4ddd5fdf79ceabeee460e950328fa87c8eaa224260e07548c6 | X40: Entertainment media retailing
...

Sheet Calculation
A1: Inputs
A2: Benchmark year | B2: 2023-24
A3: Industry | B3: Bakeries and hot bread shops
A4: Expenses shown as negatives? (Y/N) | B4: N
A5: Activity statement W1 (blank if not supplied)
A6: Expense sign factor | B6: =IF(B4="Y",-1,1) -> 1
A7: Bucket totals (SUMIFS over tblPnl) | C7: What the ATO does with it
A8: turnover | B8: =SUMIFS(tblPnl[Amount],tblPnl[Bucket],A8) -> 850000 | C8: Sales of goods and services. The ATO's turnover label.
A9: other_income | B9: =SUMIFS(tblPnl[Amount],tblPnl[Bucket],A9) -> 1200 | C9: Business income that is not sales, for example interest or grants.
A10: cost_of_sales | B10: =SUMIFS(tblPnl[Amount],tblPnl[Bucket],A10)*$B$6 -> 270000 | C10: Cost of sales, excluding any salary and wages inside it.
A11: cost_of_sales_labour | B11: =SUMIFS(tblPnl[Amount],tblPnl[Bucket],A11)*$B$6 -> 95000 | C11: Salary and wages included in cost of sales.
A12: salary_wages | B12: =SUMIFS(tblPnl[Amount],tblPnl[Bucket],A12)*$B$6 -> 175000 | C12: Salary and wages outside cost of sales.
A13: contractor_commission | B13: =SUMIFS(tblPnl[Amount],tblPnl[Bucket],A13)*$B$6 -> 7800 | C13: Contractor, subcontractor and commission expenses.
A14: associated_persons | B14: =SUMIFS(tblPnl[Amount],tblPnl[Bucket],A14)*$B$6 -> 45000 | C14: Payments to associated persons.
A15: rent | B15: =SUMIFS(tblPnl[Amount],tblPnl[Bucket],A15)*$B$6 -> 62000 | C15: Rent expenses.
A16: motor_vehicle | B16: =SUMIFS(tblPnl[Amount],tblPnl[Bucket],A16)*$B$6 -> 9500 | C16: Motor vehicle expenses.
A17: other_expense | B17: =SUMIFS(tblPnl[Amount],tblPnl[Bucket],A17)*$B$6 -> 87650 | C17: Every other expense, including superannuation and depreciation.
A18: excluded | B18: =SUMIFS(tblPnl[Amount],tblPnl[Bucket],A18) -> 2287850 | C18: Not part of the ATO calculation, for example income tax expense.
A19: Figures
A20: Sales of goods and services | B20: =B8 -> 850000
A21: Other business income | B21: =B9 -> 1200
A22: Total business income | B22: =B20+B21 -> 851200
A23: Turnover | B23: =IF(OR(B20<=0,B20*2<B22),B22,B20) -> 850000
A24: Turnover basis | B24: =IF(OR(B20<=0,B20*2<B22),"total business income","sales of goods and services") -> sales of goods and services
A25: Total expenses reported | B25: =SUM(B10:B17) -> 751950
A26: Payments to associated persons | B26: =B14 -> 45000
A27: Total expenses for ratio | B27: =B25-B26 -> 706950
A28: Cost of sales for ratio (excludes wages) | B28: =B10 -> 270000
A29: Salary and wages label (wages + cost of sales wages + associates) | B29: =B12+B11+B26 -> 315000
A30: Labour base (W1 when it exceeds the label) | B30: =IF(AND(B5<>"",B5>B29),B5,B29) -> 315000
A31: Labour (base less associates plus contractors and commission) | B31: =B30-B26+B13 -> 277800
A32: Band lookup (1E9 = no match) | B32: =SUMPRODUCT(MIN(((tblBands[Year]=B2)*(tblBands[Industry]=B3)*(((B23>tblBands[From])+((tblBands[FromInclusive]="Y")*(B23=tblBands[From])))>0)*(((tblBands[To]="")+(B23<=tblBands[To]))>0))*(ROW(tblBands[Year])-1)+(1-((tblBands[Year]=B2)*(tblBands[Industry]=B3)*(((B23>tblBands[From])+((tblBands[FromInclusive]="Y")*(B23=tblBands[From])))>0)*(((tblBands[To]="")+(B23<=tblBands[To]))>0)))*1000000000)) -> 311
A33: Band row in tblBands (0 = none) | B33: =IF(B32>=1000000000,0,B32) -> 311
A34: Turnover band | B34: =IF(B33=0,"none applies",INDEX(tblBands[Label],B33)) -> More than $750,000
A35: Industry row in tblBands (0 = not published for the year) | B35: =SUMPRODUCT(MAX((tblBands[Year]=B2)*(tblBands[Industry]=B3)*(ROW(tblBands[Year])-1))) -> 311
A36: Published key ratio | B36: =IF(B35=0,"",INDEX(tblBands[KeyRatio],B35)) -> cost_of_sales_to_turnover
A37: Key ratio used | B37: =IF(AND(B36="cost_of_sales_to_turnover",B28=0),"total_expenses_to_turnover",B36) -> cost_of_sales_to_turnover

Sheet Results
A1: Ratio | B1: Label | C1: Actual | D1: Benchmark min | E1: Benchmark max | F1: Status | G1: Key | H1: Range source
A2: cost_of_sales_to_turnover | B2: Cost of sales to turnover | C2: =IFERROR(ROUND(Calculation!B28/Calculation!B23,4),"") -> 0.3176 | D2: =IF(OR(Calculation!$B$33=0,INDEX(tblBands[CostOfSalesMin],Calculation!$B$33)=""),"",INDEX(tblBands[CostOfSalesMin],Calculation!$B$33)) -> 0.29 | E2: =IF(OR(Calculation!$B$33=0,INDEX(tblBands[CostOfSalesMax],Calculation!$B$33)=""),"",INDEX(tblBands[CostOfSalesMax],Calculation!$B$33)) -> 0.36 | F2: =IF(C2="","not calculated",IF(Calculation!$B$33=0,"no turnover band applies",IF(D2="","no benchmark in this dataset",IF(AND(C2>=D2,C2<=E2),"within",IF(C2<D2,"below","above"))))) -> within | G2: =IF(A2=Calculation!$B$37,"key","") -> key | H2: =IF(D2="","",IF(ISNUMBER(SEARCH(A2,INDEX(tblBands[PageRanges],Calculation!$B$33))),"ato_industry_page","ato_dataset")) -> ato_dataset
A3: total_expenses_to_turnover | B3: Total expenses to turnover | C3: =IFERROR(ROUND(Calculation!B27/Calculation!B23,4),"") -> 0.8317 | D3: =IF(OR(Calculation!$B$33=0,INDEX(tblBands[TotalExpensesMin],Calculation!$B$33)=""),"",INDEX(tblBands[TotalExpensesMin],Calculation!$B$33)) -> 0.82 | E3: =IF(OR(Calculation!$B$33=0,INDEX(tblBands[TotalExpensesMax],Calculation!$B$33)=""),"",INDEX(tblBands[TotalExpensesMax],Calculation!$B$33)) -> 0.9 | F3: =IF(C3="","not calculated",IF(Calculation!$B$33=0,"no turnover band applies",IF(D3="","no benchmark in this dataset",IF(AND(C3>=D3,C3<=E3),"within",IF(C3<D3,"below","above"))))) -> within | G3: =IF(A3=Calculation!$B$37,"key","") | H3: =IF(D3="","",IF(ISNUMBER(SEARCH(A3,INDEX(tblBands[PageRanges],Calculation!$B$33))),"ato_industry_page","ato_dataset")) -> ato_dataset
A4: labour_to_turnover | B4: Labour to turnover | C4: =IFERROR(ROUND(Calculation!B31/Calculation!B23,4),"") -> 0.3268 | D4: =IF(OR(Calculation!$B$33=0,INDEX(tblBands[LabourMin],Calculation!$B$33)=""),"",INDEX(tblBands[LabourMin],Calculation!$B$33)) -> 0.25 | E4: =IF(OR(Calculation!$B$33=0,INDEX(tblBands[LabourMax],Calculation!$B$33)=""),"",INDEX(tblBands[LabourMax],Calculation!$B$33)) -> 0.34 | F4: =IF(C4="","not calculated",IF(Calculation!$B$33=0,"no turnover band applies",IF(D4="","no benchmark in this dataset",IF(AND(C4>=D4,C4<=E4),"within",IF(C4<D4,"below","above"))))) -> within | G4: =IF(A4=Calculation!$B$37,"key","") | H4: =IF(D4="","",IF(ISNUMBER(SEARCH(A4,INDEX(tblBands[PageRanges],Calculation!$B$33))),"ato_industry_page","ato_dataset")) -> ato_industry_page
A5: rent_to_turnover | B5: Rent to turnover | C5: =IFERROR(ROUND(Calculation!B15/Calculation!B23,4),"") -> 0.0729 | D5: =IF(OR(Calculation!$B$33=0,INDEX(tblBands[RentMin],Calculation!$B$33)=""),"",INDEX(tblBands[RentMin],Calculation!$B$33)) -> 0.05 | E5: =IF(OR(Calculation!$B$33=0,INDEX(tblBands[RentMax],Calculation!$B$33)=""),"",INDEX(tblBands[RentMax],Calculation!$B$33)) -> 0.08 | F5: =IF(C5="","not calculated",IF(Calculation!$B$33=0,"no turnover band applies",IF(D5="","no benchmark in this dataset",IF(AND(C5>=D5,C5<=E5),"within",IF(C5<D5,"below","above"))))) -> within | G5: =IF(A5=Calculation!$B$37,"key","") | H5: =IF(D5="","",IF(ISNUMBER(SEARCH(A5,INDEX(tblBands[PageRanges],Calculation!$B$33))),"ato_industry_page","ato_dataset")) -> ato_industry_page
A6: motor_vehicle_to_turnover | B6: Motor vehicle expenses to turnover | C6: =IFERROR(ROUND(Calculation!B16/Calculation!B23,4),"") -> 0.0112 | D6: =IF(OR(Calculation!$B$33=0,INDEX(tblBands[MotorVehicleMin],Calculation!$B$33)=""),"",INDEX(tblBands[MotorVehicleMin],Calculation!$B$33)) -> 0.01 | E6: =IF(OR(Calculation!$B$33=0,INDEX(tblBands[MotorVehicleMax],Calculation!$B$33)=""),"",INDEX(tblBands[MotorVehicleMax],Calculation!$B$33)) -> 0.01 | F6: =IF(C6="","not calculated",IF(Calculation!$B$33=0,"no turnover band applies",IF(D6="","no benchmark in this dataset",IF(AND(C6>=D6,C6<=E6),"within",IF(C6<D6,"below","above"))))) -> above | G6: =IF(A6=Calculation!$B$37,"key","") | H6: =IF(D6="","",IF(ISNUMBER(SEARCH(A6,INDEX(tblBands[PageRanges],Calculation!$B$33))),"ato_industry_page","ato_dataset")) -> ato_industry_page
A8: Turnover | B8: =Calculation!B23 -> 850000
A9: Turnover band | B9: =Calculation!B34 -> More than $750,000
A10: Benchmark year and industry | B10: =Calculation!B2&" "&Calculation!B3 -> 2023-24 Bakeries and hot bread shops

Sheet Review Checks
A1: Check | B1: Result | C1: Count or value | D1: Example account
A2: Every P&L account has a recognised bucket | B2: =IF(C2=0,"PASS","BLOCKED") -> PASS | C2: =SUMPRODUCT((tblPnl[Account]<>"")*(MMULT(--(tblPnl[Bucket]={"turnover","other_income","cost_of_sales","cost_of_sales_labour","salary_wages","contractor_commission","associated_persons","rent","motor_vehicle","other_expense","excluded"}),{1;1;1;1;1;1;1;1;1;1;1})=0)) -> 0 | D2: {=IF(C2=0,"",INDEX(tblPnl[Account],SUMPRODUCT(MAX((tblPnl[Account]<>"")*(MMULT(--(tblPnl[Bucket]={"turnover","other_income","cost_of_sales","cost_of_sales_labour","salary_wages","contractor_commission","associated_persons","rent","motor_vehicle","other_expense","excluded"}),{1;1;1;1;1;1;1;1;1;1;1})=0)*(ROW(tblPnl[Account])-1)))))}
A3: No mapping is still suggested | B3: =IF(C3=0,"PASS","BLOCKED") -> PASS | C3: =SUMPRODUCT(--(TRIM(LOWER(tblMapping[Source]))="suggested")) -> 0 | D3: {=IF(C3=0,"",INDEX(tblMapping[Account],SUMPRODUCT(MAX((TRIM(LOWER(tblMapping[Source]))="suggested")*(ROW(tblMapping[Account])-1)))))}
A4: No formula or non-numeric cell in the P&L | B4: =IF(C4=0,"PASS","BLOCKED") -> PASS | C4: =SUM(tblPnl[Guard]) -> 0 | D4: {=IF(C4=0,"",INDEX(tblPnl[Account],SUMPRODUCT(MAX((tblPnl[Guard]=1)*(ROW(tblPnl[Account])-1)))))}
A5: No P&L account name appears twice | B5: =IF(C5=0,"PASS","BLOCKED") -> PASS | C5: {=SUMPRODUCT((MMULT(--(tblPnl[Key]=TRANSPOSE(tblPnl[Key])),ROW(tblPnl[Key])^0)>1)*(tblPnl[Key]<>""))} -> 0 | D5: {=IF(C5=0,"",INDEX(tblPnl[Account],SUMPRODUCT(MAX((MMULT(--(tblPnl[Key]=TRANSPOSE(tblPnl[Key])),ROW(tblPnl[Key])^0)>1)*(tblPnl[Key]<>"")*(ROW(tblPnl[Account])-1)))))}
A6: No mapping account appears twice | B6: =IF(C6=0,"PASS","BLOCKED") -> PASS | C6: {=SUMPRODUCT((MMULT(--(tblMapping[Key]=TRANSPOSE(tblMapping[Key])),ROW(tblMapping[Key])^0)>1)*(tblMapping[Key]<>""))} -> 0 | D6: {=IF(C6=0,"",INDEX(tblMapping[Account],SUMPRODUCT(MAX((MMULT(--(tblMapping[Key]=TRANSPOSE(tblMapping[Key])),ROW(tblMapping[Key])^0)>1)*(tblMapping[Key]<>"")*(ROW(tblMapping[Account])-1)))))}
A7: W1 is not negative | B7: =IF(AND(Calculation!B5<>"",Calculation!B5<0),"BLOCKED","PASS") -> PASS | C7: =Calculation!B5 -> 0
A8: Turnover is positive | B8: =IF(Calculation!B23>0,"PASS","BLOCKED") -> PASS | C8: =Calculation!B23 -> 850000
A9: Industry is published for the benchmark year | B9: =IF(Calculation!B35=0,"BLOCKED","PASS") -> PASS | C9: =Calculation!B2&" "&Calculation!B3 -> 2023-24 Bakeries and hot bread shops
A10: Turnover falls in a published band | B10: =IF(Calculation!B33=0,"REVIEW","PASS") -> PASS | C10: =Calculation!B34 -> More than $750,000
A11: Key ratio is within its range | B11: =IF(C11="within","PASS","REVIEW") -> PASS | C11: =IFERROR(INDEX(Results!F2:F6,MATCH(Calculation!B37,Results!A2:A6,0)),"not calculated") -> within
A12: No fabricated example account from the shipped bakery sample remains in the P&L | B12: =IF(C12=0,"PASS","REVIEW") -> REVIEW | C12: =SUM(tblPnl[Sample]) -> 27 | D12: {=IF(C12=0,"",INDEX(tblPnl[Account],SUMPRODUCT(MAX((tblPnl[Sample]=1)*(ROW(tblPnl[Account])-1)))))} -> Net Profit
A13: Overall status | B13: =IF(COUNTIF(B2:B12,"BLOCKED")>0,"BLOCKED",IF(COUNTIF(B2:B12,"REVIEW")>0,"REVIEW","PASS")) -> REVIEW
A15: Notes (the engine prints these as warnings; they do not change the status)
A16: =IF(Calculation!B24="total business income","Sales of goods and services are not positive or are less than half of total business income, so total business income is used as turnover. That is the ATO rule, but check the mapping.","")
A17: =IF(AND(Calculation!B5<>"",Calculation!B5>Calculation!B29),"Activity statement W1 is greater than the salary and wages label, so W1 is used in the labour ratio.","")
A18: =IF(AND(Calculation!B5="",Calculation!B11+Calculation!B12>0),"No activity statement W1 amount was supplied. The ATO uses W1 for the labour ratio when it exceeds the salary and wages figure.","") -> No activity statement W1 amount was supplied. The ATO uses W1 for the labour ratio when it exceeds the salary and wages figure.
A19: =IF(Calculation!B26=0,"No payments to associated persons were mapped. They are deducted from total expenses, so a zero here raises the total expenses ratio.","")
A20: =IF(AND(Calculation!B28>0,Calculation!B11=0),"No salary and wages were mapped inside cost of sales. The ATO excludes wages from the cost of sales ratio, so confirm none are sitting in those accounts.","")
A21: =IF(MIN(Calculation!B10:B17)<0,"An expense bucket is negative. Check the sign convention of the export, or set Calculation!B4 to Y.","")
A22: =IF(Calculation!B36="cost_of_sales_to_turnover",IF(Calculation!B28=0,"Cost of sales is the ATO key range for this industry but none was mapped, so total expenses to turnover is the key range used here.","The ATO says to use total expenses to turnover as the key range where cost of sales is only a small amount. Both ranges are reported and that judgement is yours."),"") -> The ATO says to use total expenses to turnover as the key range where cost of sales is only a small amount. Both ranges are reported and that judgement is yours.
A23: =IF(COUNTIF(Results!H2:H6,"ato_industry_page")>0,"Some ranges on Results come from the ATO's page for this industry, not the data.gov.au dataset (Range source column). The ATO says not every business reports these expenses and to use these ranges only as a guide where they apply.","") -> Some ranges on Results come from the ATO's page for this industry, not the data.gov.au dataset (Range source column). The ATO says not every business reports these expenses and to use these ranges only as a guide where they apply.

Sheet Sources & Version
A1: Item | B1: Value
A2: Workbook engine version | B2: 0.2.0
A3: Desktop Excel build used to calculate cached values | B3: Excel 16.0 build 20527
A4: 2022-23 publisher | B4: Australian Taxation Office
A5: 2022-23 dataset | B5: Small Business Benchmarks
A6: 2022-23 resource | B6: https://data.gov.au/data/dataset/591b444b-be7f-4121-8252-119a9fe07c19/resource/dfaf2207-86f4-4b5a-8847-6a0d2f8de8cd/download/small-business-benchmarks-2022-23-data.xlsx
A7: 2022-23 retrieved | B7: 2026-08-13
A8: 2022-23 sha256 | B8: ecd9ad5169fcdc4ddd5fdf79ceabeee460e950328fa87c8eaa224260e07548c6
A9: 2022-23 licence | B9: Creative Commons Attribution 2.5 Australia https://creativecommons.org/licenses/by/2.5/au/
A10: 2023-24 publisher | B10: Australian Taxation Office
A11: 2023-24 dataset | B11: Small Business Benchmarks
A12: 2023-24 resource | B12: https://data.gov.au/data/dataset/591b444b-be7f-4121-8252-119a9fe07c19/resource/db3ab8b7-e029-48de-8e7a-c61532e25496/download/small-business-benchmarks-2023-24-data.xlsx
... A20: 2023-24 industry pages caution | B20: Not all expenses are reported by every business. The ATO says to use these ranges only as a guide where they apply to the business.
